Workbook

Sheet Dashboard
A1: PAINEL DE CONTROLE — ALMOXARIFADO BOIBOM
A4: Clique em um botão para abrir a aba correspondente.
A6: 📦 ANALISAR ESTOQUE
A9: Ver o que precisa comprar agora, mínimo/máximo por item
A11: 🛒 ANALISAR COMPRAS
A14: Pedidos pendentes, solicitados e recebidos
A16: 🗄️ BASE GESTRAN
A19: Posição completa do sistema, todos os 5.480 itens
A21: 📊 ANALISAR DADOS
A24: Visão geral: itens zerados, duplicados, valor parado
A25: HISTÓRICO DE SAÍDA

Sheet Controle_Estoque
A1: CONTROLE DE ESTOQUE — O QUE COMPRAR | F1: ITENS P/ COMPRAR AGORA: | H1: =COUNTIF(G8:G44,"COMPRAR") -> 30
A2: Uma linha por produto. Preencha Produto + Setor (nome exato da Base_Gestran) e Mínimo/Máximo — o resto roda sozinho. Sem duplicar: cada item aparece uma vez só. | F2: ITENS OK / ACIMA DO MÁXIMO: | H2: =COUNTIF(G8:G44,"OK")+COUNTIF(G8:G44,"ACIMA DO MÁXIMO") -> 7
A4: Regra: quando Saldo Atual ≤ Mínimo, o Status vira COMPRAR e sugere repor até o Máximo.
A7: Produto | B7: Setor / Almoxarifado | C7: Saldo Atual (sistema) | D7: Consumo Médio Semanal (referência) | E7: Mínimo (você define) | F7: Máximo (você define) | G7: Status | H7: Qtd Sugerida de Compra | I7: Observações
A8: LAMPADA H4 24V PHILLIPS | B8: ALMOXARIFADO | C8: =IF(A8="","",SUMIFS(Base_Gestran!$E$2:$E$5481,Base_Gestran!$A$2:$A$5481,A8,Base_Gestran!$C$2:$C$5481,B8)) -> 1 | D8: =IF(A8="","",IF(SUMIFS(Historico_Saidas!$D$6:$D$5000,Historico_Saidas!$A$6:$A$5000,A8,Historico_Saidas!$B$6:$B$5000,B8)=0,"",SUMIFS(Historico_Saidas!$D$6:$D$5000,Historico_Saidas!$A$6:$A$5000,A8,Historico_Saidas!$B$6:$B$5000,B8)/Historico_Saidas!$G$1)) -> 2.3939503 | E8: 1 | F8: 3 | G8: =IF(OR(A8="",C8="",E8=""),"",IF(C8<=E8,"COMPRAR",IF(C8>F8,"ACIMA DO MÁXIMO","OK"))) -> COMPRAR | H8: =IF(G8="COMPRAR",MAX(F8-C8,0),0) -> 2
A9: LAMPADA H7 24V PHILLIPS | B9: ALMOXARIFADO | C9: =IF(A9="","",SUMIFS(Base_Gestran!$E$2:$E$5481,Base_Gestran!$A$2:$A$5481,A9,Base_Gestran!$C$2:$C$5481,B9)) -> 8 | D9: =IF(A9="","",IF(SUMIFS(Historico_Saidas!$D$6:$D$5000,Historico_Saidas!$A$6:$A$5000,A9,Historico_Saidas!$B$6:$B$5000,B9)=0,"",SUMIFS(Historico_Saidas!$D$6:$D$5000,Historico_Saidas!$A$6:$A$5000,A9,Historico_Saidas!$B$6:$B$5000,B9)/Historico_Saidas!$G$1)) -> 2.0362336 | E9: 1 | F9: 3 | G9: =IF(OR(A9="",C9="",E9=""),"",IF(C9<=E9,"COMPRAR",IF(C9>F9,"ACIMA DO MÁXIMO","OK"))) -> ACIMA DO MÁXIMO | H9: =IF(G9="COMPRAR",MAX(F9-C9,0),0) -> 0
A10: BUZINA BIBI 24V | B10: ALMOXARIFADO | C10: =IF(A10="","",SUMIFS(Base_Gestran!$E$2:$E$5481,Base_Gestran!$A$2:$A$5481,A10,Base_Gestran!$C$2:$C$5481,B10)) -> 1 | D10: =IF(A10="","",IF(SUMIFS(Historico_Saidas!$D$6:$D$5000,Historico_Saidas!$A$6:$A$5000,A10,Historico_Saidas!$B$6:$B$5000,B10)=0,"",SUMIFS(Historico_Saidas!$D$6:$D$5000,Historico_Saidas!$A$6:$A$5000,A10,Historico_Saidas!$B$6:$B$5000,B10)/Historico_Saidas!$G$1)) -> 0.60536673 | E10: 2 | F10: 4 | G10: =IF(OR(A10="",C10="",E10=""),"",IF(C10<=E10,"COMPRAR",IF(C10>F10,"ACIMA DO MÁXIMO","OK"))) -> COMPRAR | H10: =IF(G10="COMPRAR",MAX(F10-C10,0),0) -> 3
A11: RESERVATORIO DE ÁGUA ACCELO TANQUE EXPANSÃO PARALELA | B11: ALMOXARIFADO | C11: =IF(A11="","",SUMIFS(Base_Gestran!$E$2:$E$5481,Base_Gestran!$A$2:$A$5481,A11,Base_Gestran!$C$2:$C$5481,B11)) -> 4 | D11: =IF(A11="","",IF(SUMIFS(Historico_Saidas!$D$6:$D$5000,Historico_Saidas!$A$6:$A$5000,A11,Historico_Saidas!$B$6:$B$5000,B11)=0,"",SUMIFS(Historico_Saidas!$D$6:$D$5000,Historico_Saidas!$A$6:$A$5000,A11,Historico_Saidas!$B$6:$B$5000,B11)/Historico_Saidas!$G$1)) -> 0.19261669 | E11: 1 | F11: 2 | G11: =IF(OR(A11="",C11="",E11=""),"",IF(C11<=E11,"COMPRAR",IF(C11>F11,"ACIMA DO MÁXIMO","OK"))) -> ACIMA DO MÁXIMO | H11: =IF(G11="COMPRAR",MAX(F11-C11,0),0) -> 0
A12: ROLAMENTO DE CENTRO 45MM | B12: ALMOXARIFADO | C12: =IF(A12="","",SUMIFS(Base_Gestran!$E$2:$E$5481,Base_Gestran!$A$2:$A$5481,A12,Base_Gestran!$C$2:$C$5481,B12)) -> 0 | D12: =IF(A12="","",IF(SUMIFS(Historico_Saidas!$D$6:$D$5000,Historico_Saidas!$A$6:$A$5000,A12,Historico_Saidas!$B$6:$B$5000,B12)=0,"",SUMIFS(Historico_Saidas!$D$6:$D$5000,Historico_Saidas!$A$6:$A$5000,A12,Historico_Saidas!$B$6:$B$5000,B12)/Historico_Saidas!$G$1)) -> 0.082550009 | E12: 1 | F12: 3 | G12: =IF(OR(A12="",C12="",E12=""),"",IF(C12<=E12,"COMPRAR",IF(C12>F12,"ACIMA DO MÁXIMO","OK"))) -> COMPRAR | H12: =IF(G12="COMPRAR",MAX(F12-C12,0),0) -> 3
A13: TANQUE DE LIQUIDO SA1 AC/AE | B13: ALMOXARIFADO | C13: =IF(A13="","",SUMIFS(Base_Gestran!$E$2:$E$5481,Base_Gestran!$A$2:$A$5481,A13,Base_Gestran!$C$2:$C$5481,B13)) -> 1 | D13: =IF(A13="","",IF(SUMIFS(Historico_Saidas!$D$6:$D$5000,Historico_Saidas!$A$6:$A$5000,A13,Historico_Saidas!$B$6:$B$5000,B13)=0,"",SUMIFS(Historico_Saidas!$D$6:$D$5000,Historico_Saidas!$A$6:$A$5000,A13,Historico_Saidas!$B$6:$B$5000,B13)/Historico_Saidas!$G$1)) -> 0.055033339 | E13: 1 | F13: 1 | G13: =IF(OR(A13="",C13="",E13=""),"",IF(C13<=E13,"COMPRAR",IF(C13>F13,"ACIMA DO MÁXIMO","OK"))) -> COMPRAR | H13: =IF(G13="COMPRAR",MAX(F13-C13,0),0) -> 0 | I13: aguardando pra dar saida
A14: OLEO 175PZ DANFOS 160PZ | B14: ALMOXARIFADO | C14: =IF(A14="","",SUMIFS(Base_Gestran!$E$2:$E$5481,Base_Gestran!$A$2:$A$5481,A14,Base_Gestran!$C$2:$C$5481,B14)) -> 5 | D14: =IF(A14="","",IF(SUMIFS(Historico_Saidas!$D$6:$D$5000,Historico_Saidas!$A$6:$A$5000,A14,Historico_Saidas!$B$6:$B$5000,B14)=0,"",SUMIFS(Historico_Saidas!$D$6:$D$5000,Historico_Saidas!$A$6:$A$5000,A14,Historico_Saidas!$B$6:$B$5000,B14)/Historico_Saidas!$G$1)) -> 0.02751667 | E14: 1 | F14: 3 | G14: =IF(OR(A14="",C14="",E14=""),"",IF(C14<=E14,"COMPRAR",IF(C14>F14,"ACIMA DO MÁXIMO","OK"))) -> ACIMA DO MÁXIMO | H14: =IF(G14="COMPRAR",MAX(F14-C14,0),0) -> 0
A15: CONJ ALAVANCA DO CONTRA PESO DE AÇO A 0002643224 | B15: ALMOXARIFADO 1- MANUTENCAO TRANSPORTE | C15: =IF(A15="","",SUMIFS(Base_Gestran!$E$2:$E$5481,Base_Gestran!$A$2:$A$5481,A15,Base_Gestran!$C$2:$C$5481,B15)) -> 1 | D15: =IF(A15="","",IF(SUMIFS(Historico_Saidas!$D$6:$D$5000,Historico_Saidas!$A$6:$A$5000,A15,Historico_Saidas!$B$6:$B$5000,B15)=0,"",SUMIFS(Historico_Saidas!$D$6:$D$5000,Historico_Saidas!$A$6:$A$5000,A15,Historico_Saidas!$B$6:$B$5000,B15)/Historico_Saidas!$G$1)) | E15: 1 | F15: 1 | G15: =IF(OR(A15="",C15="",E15=""),"",IF(C15<=E15,"COMPRAR",IF(C15>F15,"ACIMA DO MÁXIMO","OK"))) -> COMPRAR | H15: =IF(G15="COMPRAR",MAX(F15-C15,0),0) -> 0
A16: BOMBA D'AGUA (OM 904/906) | B16: ALMOXARIFADO 1- MANUTENCAO TRANSPORTE | C16: =IF(A16="","",SUMIFS(Base_Gestran!$E$2:$E$5481,Base_Gestran!$A$2:$A$5481,A16,Base_Gestran!$C$2:$C$5481,B16)) -> 1 | D16: =IF(A16="","",IF(SUMIFS(Historico_Saidas!$D$6:$D$5000,Historico_Saidas!$A$6:$A$5000,A16,Historico_Saidas!$B$6:$B$5000,B16)=0,"",SUMIFS(Historico_Saidas!$D$6:$D$5000,Historico_Saidas!$A$6:$A$5000,A16,Historico_Saidas!$B$6:$B$5000,B16)/Historico_Saidas!$G$1)) | E16: 1 | F16: 1 | G16: =IF(OR(A16="",C16="",E16=""),"",IF(C16<=E16,"COMPRAR",IF(C16>F16,"ACIMA DO MÁXIMO","OK"))) -> COMPRAR | H16: =IF(G16="COMPRAR",MAX(F16-C16,0),0) -> 0
A17: PAPEL HIGIENICO ROLAO 8X300 | B17: ALMOXARIFADO 5- LIMPEZA | C17: =IF(A17="","",SUMIFS(Base_Gestran!$E$2:$E$5481,Base_Gestran!$A$2:$A$5481,A17,Base_Gestran!$C$2:$C$5481,B17)) -> 794 | D17: =IF(A17="","",IF(SUMIFS(Historico_Saidas!$D$6:$D$5000,Historico_Saidas!$A$6:$A$5000,A17,Historico_Saidas!$B$6:$B$5000,B17)=0,"",SUMIFS(Historico_Saidas!$D$6:$D$5000,Historico_Saidas!$A$6:$A$5000,A17,Historico_Saidas!$B$6:$B$5000,B17)/Historico_Saidas!$G$1)) -> 0.46778338 | E17: 1 | F17: 5 | G17: =IF(OR(A17="",C17="",E17=""),"",IF(C17<=E17,"COMPRAR",IF(C17>F17,"ACIMA DO MÁXIMO","OK"))) -> ACIMA DO MÁXIMO | H17: =IF(G17="COMPRAR",MAX(F17-C17,0),0) -> 0
A18: SIKAFLEX BRANCO | B18: ALMOXARIFADO | C18: =IF(A18="","",SUMIFS(Base_Gestran!$E$2:$E$5481,Base_Gestran!$A$2:$A$5481,A18,Base_Gestran!$C$2:$C$5481,B18)) -> 0 | D18: =IF(A18="","",IF(SUMIFS(Historico_Saidas!$D$6:$D$5000,Historico_Saidas!$A$6:$A$5000,A18,Historico_Saidas!$B$6:$B$5000,B18)=0,"",SUMIFS(Historico_Saidas!$D$6:$D$5000,Historico_Saidas!$A$6:$A$5000,A18,Historico_Saidas!$B$6:$B$5000,B18)/Historico_Saidas!$G$1)) | E18: 1 | F18: 2 | G18: =IF(OR(A18="",C18="",E18=""),"",IF(C18<=E18,"COMPRAR",IF(C18>F18,"ACIMA DO MÁXIMO","OK"))) -> COMPRAR | H18: =IF(G18="COMPRAR",MAX(F18-C18,0),0) -> 2
A19: RODA COLSON PNEUMATICA 350-4 R.7 | B19: ALMOXARIFADO | C19: =IF(A19="","",SUMIFS(Base_Gestran!$E$2:$E$5481,Base_Gestran!$A$2:$A$5481,A19,Base_Gestran!$C$2:$C$5481,B19)) -> 6 | D19: =IF(A19="","",IF(SUMIFS(Historico_Saidas!$D$6:$D$5000,Historico_Saidas!$A$6:$A$5000,A19,Historico_Saidas!$B$6:$B$5000,B19)=0,"",SUMIFS(Historico_Saidas!$D$6:$D$5000,Historico_Saidas!$A$6:$A$5000,A19,Historico_Saidas!$B$6:$B$5000,B19)/Historico_Saidas!$G$1)) -> 4.5952838 | E19: 2 | F19: 4 | G19: =IF(OR(A19="",C19="",E19=""),"",IF(C19<=E19,"COMPRAR",IF(C19>F19,"ACIMA DO MÁXIMO","OK"))) -> ACIMA DO MÁXIMO | H19: =IF(G19="COMPRAR",MAX(F19-C19,0),0) -> 0
A20: FITA ROTULADOR COMPATIVEL C/ TZE-641 18MM AMARELA Pt-e550wvp | B20: ALMOXARIFADO | C20: =IF(A20="","",SUMIFS(Base_Gestran!$E$2:$E$5481,Base_Gestran!$A$2:$A$5481,A20,Base_Gestran!$C$2:$C$5481,B20)) -> 0 | D20: =IF(A20="","",IF(SUMIFS(Historico_Saidas!$D$6:$D$5000,Historico_Saidas!$A$6:$A$5000,A20,Historico_Saidas!$B$6:$B$5000,B20)=0,"",SUMIFS(Historico_Saidas!$D$6:$D$5000,Historico_Saidas!$A$6:$A$5000,A20,Historico_Saidas!$B$6:$B$5000,B20)/Historico_Saidas!$G$1)) | E20: 4 | F20: 8 | G20: =IF(OR(A20="",C20="",E20=""),"",IF(C20<=E20,"COMPRAR",IF(C20>F20,"ACIMA DO MÁXIMO","OK"))) -> COMPRAR | H20: =IF(G20="COMPRAR",MAX(F20-C20,0),0) -> 8
A21: ANTISSEPTICO BUCAL REFIL 1 LITRO | B21: ALMOXARIFADO | C21: =IF(A21="","",SUMIFS(Base_Gestran!$E$2:$E$5481,Base_Gestran!$A$2:$A$5481,A21,Base_Gestran!$C$2:$C$5481,B21)) -> 1 | D21: =IF(A21="","",IF(SUMIFS(Historico_Saidas!$D$6:$D$5000,Historico_Saidas!$A$6:$A$5000,A21,Historico_Saidas!$B$6:$B$5000,B21)=0,"",SUMIFS(Historico_Saidas!$D$6:$D$5000,Historico_Saidas!$A$6:$A$5000,A21,Historico_Saidas!$B$6:$B$5000,B21)/Historico_Saidas!$G$1)) -> 0.41275005 | E21: 5 | F21: 9 | G21: =IF(OR(A21="",C21="",E21=""),"",IF(C21<=E21,"COMPRAR",IF(C21>F21,"ACIMA DO MÁXIMO","OK"))) -> COMPRAR | H21: =IF(G21="COMPRAR",MAX(F21-C21,0),0) -> 8
A22: PEDRA PERFUMADA SANÍTARIA (REDE PLÁSTICA) HARPIC | B22: ALMOXARIFADO | C22: =IF(A22="","",SUMIFS(Base_Gestran!$E$2:$E$5481,Base_Gestran!$A$2:$A$5481,A22,Base_Gestran!$C$2:$C$5481,B22)) -> 0 | D22: =IF(A22="","",IF(SUMIFS(Historico_Saidas!$D$6:$D$5000,Historico_Saidas!$A$6:$A$5000,A22,Historico_Saidas!$B$6:$B$5000,B22)=0,"",SUMIFS(Historico_Saidas!$D$6:$D$5000,Historico_Saidas!$A$6:$A$5000,A22,Historico_Saidas!$B$6:$B$5000,B22)/Historico_Saidas!$G$1)) | E22: 6 | F22: 10 | G22: =IF(OR(A22="",C22="",E22=""),"",IF(C22<=E22,"COMPRAR",IF(C22>F22,"ACIMA DO MÁXIMO","OK"))) -> COMPRAR | H22: =IF(G22="COMPRAR",MAX(F22-C22,0),0) -> 10
A23: PERFEX | B23: ALMOXARIFADO | C23: =IF(A23="","",SUMIFS(Base_Gestran!$E$2:$E$5481,Base_Gestran!$A$2:$A$5481,A23,Base_Gestran!$C$2:$C$5481,B23)) -> 0 | D23: =IF(A23="","",IF(SUMIFS(Historico_Saidas!$D$6:$D$5000,Historico_Saidas!$A$6:$A$5000,A23,Historico_Saidas!$B$6:$B$5000,B23)=0,"",SUMIFS(Historico_Saidas!$D$6:$D$5000,Historico_Saidas!$A$6:$A$5000,A23,Historico_Saidas!$B$6:$B$5000,B23)/Historico_Saidas!$G$1)) | E23: 7 | F23: 11 | G23: =IF(OR(A23="",C23="",E23=""),"",IF(C23<=E23,"COMPRAR",IF(C23>F23,"ACIMA DO MÁXIMO","OK"))) -> COMPRAR | H23: =IF(G23="COMPRAR",MAX(F23-C23,0),0) -> 11
A24: PAPEL HIGIENICO ROLAO 8X300 | B24: ALMOXARIFADO 5- LIMPEZA | C24: =IF(A24="","",SUMIFS(Base_Gestran!$E$2:$E$5481,Base_Gestran!$A$2:$A$5481,A24,Base_Gestran!$C$2:$C$5481,B24)) -> 794 | D24: =IF(A24="","",IF(SUMIFS(Historico_Saidas!$D$6:$D$5000,Historico_Saidas!$A$6:$A$5000,A24,Historico_Saidas!$B$6:$B$5000,B24)=0,"",SUMIFS(Historico_Saidas!$D$6:$D$5000,Historico_Saidas!$A$6:$A$5000,A24,Historico_Saidas!$B$6:$B$5000,B24)/Historico_Saidas!$G$1)) -> 0.46778338 | E24: 8 | F24: 12 | G24: =IF(OR(A24="",C24="",E24=""),"",IF(C24<=E24,"COMPRAR",IF(C24>F24,"ACIMA DO MÁXIMO","OK"))) -> ACIMA DO MÁXIMO | H24: =IF(G24="COMPRAR",MAX(F24-C24,0),0) -> 0
A25: BATERIA 100A (USAMOS A VELHA COMO BASE DE TROCA PARA ABATER NO VALOR) | B25: ALMOXARIFADO | C25: =IF(A25="","",SUMIFS(Base_Gestran!$E$2:$E$5481,Base_Gestran!$A$2:$A$5481,A25,Base_Gestran!$C$2:$C$5481,B25)) -> 0 | D25: =IF(A25="","",IF(SUMIFS(Historico_Saidas!$D$6:$D$5000,Historico_Saidas!$A$6:$A$5000,A25,Historico_Saidas!$B$6:$B$5000,B25)=0,"",SUMIFS(Historico_Saidas!$D$6:$D$5000,Historico_Saidas!$A$6:$A$5000,A25,Historico_Saidas!$B$6:$B$5000,B25)/Historico_Saidas!$G$1)) | E25: 9 | F25: 13 | G25: =IF(OR(A25="",C25="",E25=""),"",IF(C25<=E25,"COMPRAR",IF(C25>F25,"ACIMA DO MÁXIMO","OK"))) -> COMPRAR | H25: =IF(G25="COMPRAR",MAX(F25-C25,0),0) -> 13
... A48: LANTERNA LATERAL LED REDONDA VER/LAR/CRISTAL | B48: ALMOXARIFADO | C48: =IF(A48="","",SUMIFS(Base_Gestran!$E$2:$E$5481,Base_Gestran!$A$2:$A$5481,A48,Base_Gestran!$C$2:$C$5481,B48)) -> 5 | D48: =IF(A48="","",IF(SUMIFS(Historico_Saidas!$D$6:$D$5000,Historico_Saidas!$A$6:$A$5000,A48,Historico_Saidas!$B$6:$B$5000,B48)=0,"",SUMIFS(Historico_Saidas!$D$6:$D$5000,Historico_Saidas!$A$6:$A$5000,A48,Historico_Saidas!$B$6:$B$5000,B48)/Historico_Saidas!$G$1)) -> 1.7610669 | E48: 32 | F48: 36 | G48: =IF(OR(A48="",C48="",E48=""),"",IF(C48<=E48,"COMPRAR",IF(C48>F48,"ACIMA DO MÁXIMO","OK"))) -> COMPRAR | H48: =IF(G48="COMPRAR",MAX(F48-C48,0),0) -> 31
A49: DUREX PACOTES COM 5 | C49: =IF(A49="","",SUMIFS(Base_Gestran!$E$2:$E$5481,Base_Gestran!$A$2:$A$5481,A49,Base_Gestran!$C$2:$C$5481,B49)) -> 0 | D49: =IF(A49="","",IF(SUMIFS(Historico_Saidas!$D$6:$D$5000,Historico_Saidas!$A$6:$A$5000,A49,Historico_Saidas!$B$6:$B$5000,B49)=0,"",SUMIFS(Historico_Saidas!$D$6:$D$5000,Historico_Saidas!$A$6:$A$5000,A49,Historico_Saidas!$B$6:$B$5000,B49)/Historico_Saidas!$G$1)) | G49: =IF(OR(A49="",C49="",E49=""),"",IF(C49<=E49,"COMPRAR",IF(C49>F49,"ACIMA DO MÁXIMO","OK"))) | H49: =IF(G49="COMPRAR",MAX(F49-C49,0),0) -> 0
A50: SACOLA COM ALÇA 50X60 | C50: =IF(A50="","",SUMIFS(Base_Gestran!$E$2:$E$5481,Base_Gestran!$A$2:$A$5481,A50,Base_Gestran!$C$2:$C$5481,B50)) -> 0 | D50: =IF(A50="","",IF(SUMIFS(Historico_Saidas!$D$6:$D$5000,Historico_Saidas!$A$6:$A$5000,A50,Historico_Saidas!$B$6:$B$5000,B50)=0,"",SUMIFS(Historico_Saidas!$D$6:$D$5000,Historico_Saidas!$A$6:$A$5000,A50,Historico_Saidas!$B$6:$B$5000,B50)/Historico_Saidas!$G$1)) | G50: =IF(OR(A50="",C50="",E50=""),"",IF(C50<=E50,"COMPRAR",IF(C50>F50,"ACIMA DO MÁXIMO","OK"))) | H50: =IF(G50="COMPRAR",MAX(F50-C50,0),0) -> 0
A51: STRECTH | C51: =IF(A51="","",SUMIFS(Base_Gestran!$E$2:$E$5481,Base_Gestran!$A$2:$A$5481,A51,Base_Gestran!$C$2:$C$5481,B51)) -> 0 | D51: =IF(A51="","",IF(SUMIFS(Historico_Saidas!$D$6:$D$5000,Historico_Saidas!$A$6:$A$5000,A51,Historico_Saidas!$B$6:$B$5000,B51)=0,"",SUMIFS(Historico_Saidas!$D$6:$D$5000,Historico_Saidas!$A$6:$A$5000,A51,Historico_Saidas!$B$6:$B$5000,B51)/Historico_Saidas!$G$1)) | G51: =IF(OR(A51="",C51="",E51=""),"",IF(C51<=E51,"COMPRAR",IF(C51>F51,"ACIMA DO MÁXIMO","OK"))) | H51: =IF(G51="COMPRAR",MAX(F51-C51,0),0) -> 0
A52: RESMA A4 | C52: =IF(A52="","",SUMIFS(Base_Gestran!$E$2:$E$5481,Base_Gestran!$A$2:$A$5481,A52,Base_Gestran!$C$2:$C$5481,B52)) -> 0 | D52: =IF(A52="","",IF(SUMIFS(Historico_Saidas!$D$6:$D$5000,Historico_Saidas!$A$6:$A$5000,A52,Historico_Saidas!$B$6:$B$5000,B52)=0,"",SUMIFS(Historico_Saidas!$D$6:$D$5000,Historico_Saidas!$A$6:$A$5000,A52,Historico_Saidas!$B$6:$B$5000,B52)/Historico_Saidas!$G$1)) | G52: =IF(OR(A52="",C52="",E52=""),"",IF(C52<=E52,"COMPRAR",IF(C52>F52,"ACIMA DO MÁXIMO","OK"))) | H52: =IF(G52="COMPRAR",MAX(F52-C52,0),0) -> 0
A53: LUVA | C53: =IF(A53="","",SUMIFS(Base_Gestran!$E$2:$E$5481,Base_Gestran!$A$2:$A$5481,A53,Base_Gestran!$C$2:$C$5481,B53)) -> 0 | D53: =IF(A53="","",IF(SUMIFS(Historico_Saidas!$D$6:$D$5000,Historico_Saidas!$A$6:$A$5000,A53,Historico_Saidas!$B$6:$B$5000,B53)=0,"",SUMIFS(Historico_Saidas!$D$6:$D$5000,Historico_Saidas!$A$6:$A$5000,A53,Historico_Saidas!$B$6:$B$5000,B53)/Historico_Saidas!$G$1)) | G53: =IF(OR(A53="",C53="",E53=""),"",IF(C53<=E53,"COMPRAR",IF(C53>F53,"ACIMA DO MÁXIMO","OK"))) | H53: =IF(G53="COMPRAR",MAX(F53-C53,0),0) -> 0
A54: CORDA P/BOI | C54: =IF(A54="","",SUMIFS(Base_Gestran!$E$2:$E$5481,Base_Gestran!$A$2:$A$5481,A54,Base_Gestran!$C$2:$C$5481,B54)) -> 0 | D54: =IF(A54="","",IF(SUMIFS(Historico_Saidas!$D$6:$D$5000,Historico_Saidas!$A$6:$A$5000,A54,Historico_Saidas!$B$6:$B$5000,B54)=0,"",SUMIFS(Historico_Saidas!$D$6:$D$5000,Historico_Saidas!$A$6:$A$5000,A54,Historico_Saidas!$B$6:$B$5000,B54)/Historico_Saidas!$G$1)) | G54: =IF(OR(A54="",C54="",E54=""),"",IF(C54<=E54,"COMPRAR",IF(C54>F54,"ACIMA DO MÁXIMO","OK"))) | H54: =IF(G54="COMPRAR",MAX(F54-C54,0),0) -> 0
A55: CORDA AMARRAR CAMINHﾃグ | C55: =IF(A55="","",SUMIFS(Base_Gestran!$E$2:$E$5481,Base_Gestran!$A$2:$A$5481,A55,Base_Gestran!$C$2:$C$5481,B55)) -> 0 | D55: =IF(A55="","",IF(SUMIFS(Historico_Saidas!$D$6:$D$5000,Historico_Saidas!$A$6:$A$5000,A55,Historico_Saidas!$B$6:$B$5000,B55)=0,"",SUMIFS(Historico_Saidas!$D$6:$D$5000,Historico_Saidas!$A$6:$A$5000,A55,Historico_Saidas!$B$6:$B$5000,B55)/Historico_Saidas!$G$1)) | G55: =IF(OR(A55="",C55="",E55=""),"",IF(C55<=E55,"COMPRAR",IF(C55>F55,"ACIMA DO MÁXIMO","OK"))) | H55: =IF(G55="COMPRAR",MAX(F55-C55,0),0) -> 0
A56: PARAFUSO DE CAIXA | C56: =IF(A56="","",SUMIFS(Base_Gestran!$E$2:$E$5481,Base_Gestran!$A$2:$A$5481,A56,Base_Gestran!$C$2:$C$5481,B56)) -> 0 | D56: =IF(A56="","",IF(SUMIFS(Historico_Saidas!$D$6:$D$5000,Historico_Saidas!$A$6:$A$5000,A56,Historico_Saidas!$B$6:$B$5000,B56)=0,"",SUMIFS(Historico_Saidas!$D$6:$D$5000,Historico_Saidas!$A$6:$A$5000,A56,Historico_Saidas!$B$6:$B$5000,B56)/Historico_Saidas!$G$1)) | G56: =IF(OR(A56="",C56="",E56=""),"",IF(C56<=E56,"COMPRAR",IF(C56>F56,"ACIMA DO MÁXIMO","OK"))) | H56: =IF(G56="COMPRAR",MAX(F56-C56,0),0) -> 0
C57: =IF(A57="","",SUMIFS(Base_Gestran!$E$2:$E$5481,Base_Gestran!$A$2:$A$5481,A57,Base_Gestran!$C$2:$C$5481,B57)) | D57: =IF(A57="","",IF(SUMIFS(Historico_Saidas!$D$6:$D$5000,Historico_Saidas!$A$6:$A$5000,A57,Historico_Saidas!$B$6:$B$5000,B57)=0,"",SUMIFS(Historico_Saidas!$D$6:$D$5000,Historico_Saidas!$A$6:$A$5000,A57,Historico_Saidas!$B$6:$B$5000,B57)/Historico_Saidas!$G$1)) | G57: =IF(OR(A57="",C57="",E57=""),"",IF(C57<=E57,"COMPRAR",IF(C57>F57,"ACIMA DO MÁXIMO","OK"))) | H57: =IF(G57="COMPRAR",MAX(F57-C57,0),0) -> 0
C58: =IF(A58="","",SUMIFS(Base_Gestran!$E$2:$E$5481,Base_Gestran!$A$2:$A$5481,A58,Base_Gestran!$C$2:$C$5481,B58)) | D58: =IF(A58="","",IF(SUMIFS(Historico_Saidas!$D$6:$D$5000,Historico_Saidas!$A$6:$A$5000,A58,Historico_Saidas!$B$6:$B$5000,B58)=0,"",SUMIFS(Historico_Saidas!$D$6:$D$5000,Historico_Saidas!$A$6:$A$5000,A58,Historico_Saidas!$B$6:$B$5000,B58)/Historico_Saidas!$G$1)) | G58: =IF(OR(A58="",C58="",E58=""),"",IF(C58<=E58,"COMPRAR",IF(C58>F58,"ACIMA DO MÁXIMO","OK"))) | H58: =IF(G58="COMPRAR",MAX(F58-C58,0),0) -> 0
C59: =IF(A59="","",SUMIFS(Base_Gestran!$E$2:$E$5481,Base_Gestran!$A$2:$A$5481,A59,Base_Gestran!$C$2:$C$5481,B59)) | D59: =IF(A59="","",IF(SUMIFS(Historico_Saidas!$D$6:$D$5000,Historico_Saidas!$A$6:$A$5000,A59,Historico_Saidas!$B$6:$B$5000,B59)=0,"",SUMIFS(Historico_Saidas!$D$6:$D$5000,Historico_Saidas!$A$6:$A$5000,A59,Historico_Saidas!$B$6:$B$5000,B59)/Historico_Saidas!$G$1)) | G59: =IF(OR(A59="",C59="",E59=""),"",IF(C59<=E59,"COMPRAR",IF(C59>F59,"ACIMA DO MÁXIMO","OK"))) | H59: =IF(G59="COMPRAR",MAX(F59-C59,0),0) -> 0
C60: =IF(A60="","",SUMIFS(Base_Gestran!$E$2:$E$5481,Base_Gestran!$A$2:$A$5481,A60,Base_Gestran!$C$2:$C$5481,B60)) | D60: =IF(A60="","",IF(SUMIFS(Historico_Saidas!$D$6:$D$5000,Historico_Saidas!$A$6:$A$5000,A60,Historico_Saidas!$B$6:$B$5000,B60)=0,"",SUMIFS(Historico_Saidas!$D$6:$D$5000,Historico_Saidas!$A$6:$A$5000,A60,Historico_Saidas!$B$6:$B$5000,B60)/Historico_Saidas!$G$1)) | G60: =IF(OR(A60="",C60="",E60=""),"",IF(C60<=E60,"COMPRAR",IF(C60>F60,"ACIMA DO MÁXIMO","OK"))) | H60: =IF(G60="COMPRAR",MAX(F60-C60,0),0) -> 0
C61: =IF(A61="","",SUMIFS(Base_Gestran!$E$2:$E$5481,Base_Gestran!$A$2:$A$5481,A61,Base_Gestran!$C$2:$C$5481,B61)) | D61: =IF(A61="","",IF(SUMIFS(Historico_Saidas!$D$6:$D$5000,Historico_Saidas!$A$6:$A$5000,A61,Historico_Saidas!$B$6:$B$5000,B61)=0,"",SUMIFS(Historico_Saidas!$D$6:$D$5000,Historico_Saidas!$A$6:$A$5000,A61,Historico_Saidas!$B$6:$B$5000,B61)/Historico_Saidas!$G$1)) | G61: =IF(OR(A61="",C61="",E61=""),"",IF(C61<=E61,"COMPRAR",IF(C61>F61,"ACIMA DO MÁXIMO","OK"))) | H61: =IF(G61="COMPRAR",MAX(F61-C61,0),0) -> 0
C62: =IF(A62="","",SUMIFS(Base_Gestran!$E$2:$E$5481,Base_Gestran!$A$2:$A$5481,A62,Base_Gestran!$C$2:$C$5481,B62)) | D62: =IF(A62="","",IF(SUMIFS(Historico_Saidas!$D$6:$D$5000,Historico_Saidas!$A$6:$A$5000,A62,Historico_Saidas!$B$6:$B$5000,B62)=0,"",SUMIFS(Historico_Saidas!$D$6:$D$5000,Historico_Saidas!$A$6:$A$5000,A62,Historico_Saidas!$B$6:$B$5000,B62)/Historico_Saidas!$G$1)) | G62: =IF(OR(A62="",C62="",E62=""),"",IF(C62<=E62,"COMPRAR",IF(C62>F62,"ACIMA DO MÁXIMO","OK"))) | H62: =IF(G62="COMPRAR",MAX(F62-C62,0),0) -> 0
C63: =IF(A63="","",SUMIFS(Base_Gestran!$E$2:$E$5481,Base_Gestran!$A$2:$A$5481,A63,Base_Gestran!$C$2:$C$5481,B63)) | D63: =IF(A63="","",IF(SUMIFS(Historico_Saidas!$D$6:$D$5000,Historico_Saidas!$A$6:$A$5000,A63,Historico_Saidas!$B$6:$B$5000,B63)=0,"",SUMIFS(Historico_Saidas!$D$6:$D$5000,Historico_Saidas!$A$6:$A$5000,A63,Historico_Saidas!$B$6:$B$5000,B63)/Historico_Saidas!$G$1)) | G63: =IF(OR(A63="",C63="",E63=""),"",IF(C63<=E63,"COMPRAR",IF(C63>F63,"ACIMA DO MÁXIMO","OK"))) | H63: =IF(G63="COMPRAR",MAX(F63-C63,0),0) -> 0
C64: =IF(A64="","",SUMIFS(Base_Gestran!$E$2:$E$5481,Base_Gestran!$A$2:$A$5481,A64,Base_Gestran!$C$2:$C$5481,B64)) | D64: =IF(A64="","",IF(SUMIFS(Historico_Saidas!$D$6:$D$5000,Historico_Saidas!$A$6:$A$5000,A64,Historico_Saidas!$B$6:$B$5000,B64)=0,"",SUMIFS(Historico_Saidas!$D$6:$D$5000,Historico_Saidas!$A$6:$A$5000,A64,Historico_Saidas!$B$6:$B$5000,B64)/Historico_Saidas!$G$1)) | G64: =IF(OR(A64="",C64="",E64=""),"",IF(C64<=E64,"COMPRAR",IF(C64>F64,"ACIMA DO MÁXIMO","OK"))) | H64: =IF(G64="COMPRAR",MAX(F64-C64,0),0) -> 0
C65: =IF(A65="","",SUMIFS(Base_Gestran!$E$2:$E$5481,Base_Gestran!$A$2:$A$5481,A65,Base_Gestran!$C$2:$C$5481,B65)) | D65: =IF(A65="","",IF(SUMIFS(Historico_Saidas!$D$6:$D$5000,Historico_Saidas!$A$6:$A$5000,A65,Historico_Saidas!$B$6:$B$5000,B65)=0,"",SUMIFS(Historico_Saidas!$D$6:$D$5000,Historico_Saidas!$A$6:$A$5000,A65,Historico_Saidas!$B$6:$B$5000,B65)/Historico_Saidas!$G$1)) | G65: =IF(OR(A65="",C65="",E65=""),"",IF(C65<=E65,"COMPRAR",IF(C65>F65,"ACIMA DO MÁXIMO","OK"))) | H65: =IF(G65="COMPRAR",MAX(F65-C65,0),0) -> 0
...

Sheet Historico_Pedidos
A1: HISTÓRICO DE PEDIDOS DE COMPRA | H1: PENDENTES: | J1: =COUNTIF(I5:I60,"PENDENTE") -> 32
A2: Registro de cada solicitação: o que foi pedido, motivo, saldo no sistema, fornecedor e status até a entrega. | H2: SOLICITADOS: | J2: =COUNTIF(I5:I60,"SOLICITADO") -> 3
I3: RECEBIDOS: | J3: =COUNTIF(I5:I60,"RECEBIDO") -> 3
A4: Data do Pedido | B4: Produto / Material | C4: Quantidade a Comprar | D4: Medida (Un/Caixa/Pct) | E4: Setor | F4: Motivo | G4: Saldo Atual (sistema) | H4: Fornecedor | I4: Situação | J4: Previsão de Entrega | K4: Observações | L4: Chave (aux)
A5: 46261 | B5: SIKAFLEX BRANCO | C5: 2 | D5: UND | E5: =IF(B5="","",IFERROR(INDEX(Base_Gestran!$C$2:$C$5481,MATCH(B5,Base_Gestran!$A$2:$A$5481,0)),"NÃO CADASTRADO")) -> NÃO CADASTRADO | F5: ESTOQUE ZERADO | G5: =IF(B5="","",SUMIFS(Base_Gestran!$E$2:$E$5481,Base_Gestran!$A$2:$A$5481,B5,Base_Gestran!$C$2:$C$5481,E5)) -> 0 | H5: CASA DO PEDREIRO | I5: PENDENTE | L5: =IF(B5="","",B5&"|"&TEXT(A5,"0")) -> SIKAFLEX BRANCO|46261
A6: 46261 | B6: FITA ROTULADOR COMPATIVEL C/ TZE-641 18MM AMARELA Pt-e550wvp | C6: 2 | D6: UND | E6: =IF(B6="","",IFERROR(INDEX(Base_Gestran!$C$2:$C$5481,MATCH(B6,Base_Gestran!$A$2:$A$5481,0)),"NÃO CADASTRADO")) -> NÃO CADASTRADO | F6: ESTOQUE ZERADO | G6: =IF(B6="","",SUMIFS(Base_Gestran!$E$2:$E$5481,Base_Gestran!$A$2:$A$5481,B6,Base_Gestran!$C$2:$C$5481,E6)) -> 0 | H6: MERCADO LIVRE | I6: PENDENTE | L6: =IF(B6="","",B6&"|"&TEXT(A6,"0")) -> FITA ROTULADOR COMPATIVEL C/ TZE-641 18MM AMARELA Pt-e550wvp|46261
A7: 46261 | B7: ANTISSEPTICO BUCAL REFIL 1 LITRO | C7: 2 | D7: UND | E7: =IF(B7="","",IFERROR(INDEX(Base_Gestran!$C$2:$C$5481,MATCH(B7,Base_Gestran!$A$2:$A$5481,0)),"NÃO CADASTRADO")) -> ALMOXARIFADO | F7: ESTOQUE BAIXO | G7: =IF(B7="","",SUMIFS(Base_Gestran!$E$2:$E$5481,Base_Gestran!$A$2:$A$5481,B7,Base_Gestran!$C$2:$C$5481,E7)) -> 1 | H7: MERCADO LIVRE | I7: PENDENTE | L7: =IF(B7="","",B7&"|"&TEXT(A7,"0")) -> ANTISSEPTICO BUCAL REFIL 1 LITRO|46261
A8: 46261 | B8: PEDRA PERFUMADA SANÍTARIA (REDE PLÁSTICA) HARPIC | C8: 10 | D8: UND | E8: =IF(B8="","",IFERROR(INDEX(Base_Gestran!$C$2:$C$5481,MATCH(B8,Base_Gestran!$A$2:$A$5481,0)),"NÃO CADASTRADO")) -> NÃO CADASTRADO | F8: ESTOQUE BAIXO | G8: =IF(B8="","",SUMIFS(Base_Gestran!$E$2:$E$5481,Base_Gestran!$A$2:$A$5481,B8,Base_Gestran!$C$2:$C$5481,E8)) -> 0 | H8: JAÉ ILHA DESCARTÁVEIS | I8: PENDENTE | L8: =IF(B8="","",B8&"|"&TEXT(A8,"0")) -> PEDRA PERFUMADA SANÍTARIA (REDE PLÁSTICA) HARPIC |46261
A9: 46261 | B9: PERFEX | C9: 2 | D9: RL | E9: =IF(B9="","",IFERROR(INDEX(Base_Gestran!$C$2:$C$5481,MATCH(B9,Base_Gestran!$A$2:$A$5481,0)),"NÃO CADASTRADO")) -> NÃO CADASTRADO | F9: ESTOQUE BAIXO | G9: =IF(B9="","",SUMIFS(Base_Gestran!$E$2:$E$5481,Base_Gestran!$A$2:$A$5481,B9,Base_Gestran!$C$2:$C$5481,E9)) -> 0 | H9: JAÉ ILHA DESCARTÁVEIS | I9: PENDENTE | L9: =IF(B9="","",B9&"|"&TEXT(A9,"0")) -> PERFEX |46261
A10: 46266 | B10: PAPEL HIGIENICO ROLAO 8X300 | C10: 4 | D10: PCT | E10: =IF(B10="","",IFERROR(INDEX(Base_Gestran!$C$2:$C$5481,MATCH(B10,Base_Gestran!$A$2:$A$5481,0)),"NÃO CADASTRADO")) -> ALMOXARIFADO 5- LIMPEZA | F10: RECEBIDO | G10: =IF(B10="","",SUMIFS(Base_Gestran!$E$2:$E$5481,Base_Gestran!$A$2:$A$5481,B10,Base_Gestran!$C$2:$C$5481,E10)) -> 794 | H10: VALOIS | I10: RECEBIDO | J10: 46269 | L10: =IF(B10="","",B10&"|"&TEXT(A10,"0")) -> PAPEL HIGIENICO ROLAO 8X300|46266
A11: 46267 | B11: BATERIA 100A (USAMOS A VELHA COMO BASE DE TROCA PARA ABATER NO VALOR) | C11: 5 | D11: UND | E11: =IF(B11="","",IFERROR(INDEX(Base_Gestran!$C$2:$C$5481,MATCH(B11,Base_Gestran!$A$2:$A$5481,0)),"NÃO CADASTRADO")) -> NÃO CADASTRADO | F11: RECEBIDO | G11: =IF(B11="","",SUMIFS(Base_Gestran!$E$2:$E$5481,Base_Gestran!$A$2:$A$5481,B11,Base_Gestran!$C$2:$C$5481,E11)) -> 0 | H11: ROBSON BATERIAS | I11: RECEBIDO | J11: 46281 | L11: =IF(B11="","",B11&"|"&TEXT(A11,"0")) -> BATERIA 100A (USAMOS A VELHA COMO BASE DE TROCA PARA ABATER NO VALOR)|46267
A12: 46267 | B12: VASSOURÃO DE INOX | C12: 2 | D12: UND | E12: =IF(B12="","",IFERROR(INDEX(Base_Gestran!$C$2:$C$5481,MATCH(B12,Base_Gestran!$A$2:$A$5481,0)),"NÃO CADASTRADO")) -> NÃO CADASTRADO | F12: ESTOQUE ZERADO | G12: =IF(B12="","",SUMIFS(Base_Gestran!$E$2:$E$5481,Base_Gestran!$A$2:$A$5481,B12,Base_Gestran!$C$2:$C$5481,E12)) -> 0 | H12: MERCADO LIVRE | I12: PENDENTE | L12: =IF(B12="","",B12&"|"&TEXT(A12,"0")) -> VASSOURÃO DE INOX |46267
A13: 46267 | B13: FILTRO DE AR VW | C13: 2 | D13: UND | E13: =IF(B13="","",IFERROR(INDEX(Base_Gestran!$C$2:$C$5481,MATCH(B13,Base_Gestran!$A$2:$A$5481,0)),"NÃO CADASTRADO")) -> NÃO CADASTRADO | F13: ESTOQUE ZERADO | G13: =IF(B13="","",SUMIFS(Base_Gestran!$E$2:$E$5481,Base_Gestran!$A$2:$A$5481,B13,Base_Gestran!$C$2:$C$5481,E13)) -> 0 | H13: TRANSRIO | I13: PENDENTE | L13: =IF(B13="","",B13&"|"&TEXT(A13,"0")) -> FILTRO DE AR VW |46267
A14: 46267 | B14: FILTRO LUBRIFICANTE OMD2RO115403 VW | C14: 2 | D14: UND | E14: =IF(B14="","",IFERROR(INDEX(Base_Gestran!$C$2:$C$5481,MATCH(B14,Base_Gestran!$A$2:$A$5481,0)),"NÃO CADASTRADO")) -> NÃO CADASTRADO | F14: ESTOQUE ZERADO | G14: =IF(B14="","",SUMIFS(Base_Gestran!$E$2:$E$5481,Base_Gestran!$A$2:$A$5481,B14,Base_Gestran!$C$2:$C$5481,E14)) -> 0 | H14: TRANSRIO | I14: PENDENTE | L14: =IF(B14="","",B14&"|"&TEXT(A14,"0")) -> FILTRO LUBRIFICANTE OMD2RO115403 VW|46267
A15: 46267 | B15: FILTRO DE COMBUSTIVEL OMD2PO127177 | C15: 2 | D15: UND | E15: =IF(B15="","",IFERROR(INDEX(Base_Gestran!$C$2:$C$5481,MATCH(B15,Base_Gestran!$A$2:$A$5481,0)),"NÃO CADASTRADO")) -> ALMOXARIFADO 1- MANUTENCAO TRANSPORTE | F15: ESTOQUE BAIXO | G15: =IF(B15="","",SUMIFS(Base_Gestran!$E$2:$E$5481,Base_Gestran!$A$2:$A$5481,B15,Base_Gestran!$C$2:$C$5481,E15)) -> 4 | H15: TRANSRIO | I15: PENDENTE | L15: =IF(B15="","",B15&"|"&TEXT(A15,"0")) -> FILTRO DE COMBUSTIVEL OMD2PO127177|46267
A16: 46267 | B16: JAPONA NYLON AZUL MOTORISTA (M) | C16: 4 | D16: UND | E16: =IF(B16="","",IFERROR(INDEX(Base_Gestran!$C$2:$C$5481,MATCH(B16,Base_Gestran!$A$2:$A$5481,0)),"NÃO CADASTRADO")) -> ALMOXARIFADO 9- LOGÍSTICA | F16: ESTOQUE ZERADO | G16: =IF(B16="","",SUMIFS(Base_Gestran!$E$2:$E$5481,Base_Gestran!$A$2:$A$5481,B16,Base_Gestran!$C$2:$C$5481,E16)) -> 4 | H16: PAMCOLD | I16: PENDENTE | L16: =IF(B16="","",B16&"|"&TEXT(A16,"0")) -> JAPONA NYLON AZUL MOTORISTA (M)|46267
A17: 46267 | B17: JAPONA NYLON AZUL MOTORISTA (G) | C17: 4 | D17: UND | E17: =IF(B17="","",IFERROR(INDEX(Base_Gestran!$C$2:$C$5481,MATCH(B17,Base_Gestran!$A$2:$A$5481,0)),"NÃO CADASTRADO")) -> ALMOXARIFADO 9- LOGÍSTICA | F17: ESTOQUE ZERADO | G17: =IF(B17="","",SUMIFS(Base_Gestran!$E$2:$E$5481,Base_Gestran!$A$2:$A$5481,B17,Base_Gestran!$C$2:$C$5481,E17)) -> 6 | H17: PAMCOLD | I17: PENDENTE | L17: =IF(B17="","",B17&"|"&TEXT(A17,"0")) -> JAPONA NYLON AZUL MOTORISTA (G)|46267
A18: 46267 | B18: JAPONA NYLON AZUL MOTORISTA (GG) | C18: 4 | D18: UND | E18: =IF(B18="","",IFERROR(INDEX(Base_Gestran!$C$2:$C$5481,MATCH(B18,Base_Gestran!$A$2:$A$5481,0)),"NÃO CADASTRADO")) -> ALMOXARIFADO 9- LOGÍSTICA | F18: ESTOQUE ZERADO | G18: =IF(B18="","",SUMIFS(Base_Gestran!$E$2:$E$5481,Base_Gestran!$A$2:$A$5481,B18,Base_Gestran!$C$2:$C$5481,E18)) -> 5 | H18: PAMCOLD | I18: PENDENTE | L18: =IF(B18="","",B18&"|"&TEXT(A18,"0")) -> JAPONA NYLON AZUL MOTORISTA (GG)|46267
A19: 46267 | B19: JAPONA NYLON MOTORISTA (EGG) | C19: 2 | D19: UND | E19: =IF(B19="","",IFERROR(INDEX(Base_Gestran!$C$2:$C$5481,MATCH(B19,Base_Gestran!$A$2:$A$5481,0)),"NÃO CADASTRADO")) -> ALMOXARIFADO 9- LOGÍSTICA | F19: ESTOQUE ZERADO | G19: =IF(B19="","",SUMIFS(Base_Gestran!$E$2:$E$5481,Base_Gestran!$A$2:$A$5481,B19,Base_Gestran!$C$2:$C$5481,E19)) -> 4 | H19: PAMCOLD | I19: PENDENTE | L19: =IF(B19="","",B19&"|"&TEXT(A19,"0")) -> JAPONA NYLON MOTORISTA (EGG)|46267
A20: 46267 | B20: CALÇA TÉRMICA -25° M | C20: 4 | D20: UND | E20: =IF(B20="","",IFERROR(INDEX(Base_Gestran!$C$2:$C$5481,MATCH(B20,Base_Gestran!$A$2:$A$5481,0)),"NÃO CADASTRADO")) -> NÃO CADASTRADO | F20: ESTOQUE ZERADO | G20: =IF(B20="","",SUMIFS(Base_Gestran!$E$2:$E$5481,Base_Gestran!$A$2:$A$5481,B20,Base_Gestran!$C$2:$C$5481,E20)) -> 0 | H20: PAMCOLD | I20: PENDENTE | L20: =IF(B20="","",B20&"|"&TEXT(A20,"0")) -> CALÇA TÉRMICA -25° M|46267
A21: 46267 | B21: CALÇA TÉRMICA -25° G | C21: 4 | D21: UND | E21: =IF(B21="","",IFERROR(INDEX(Base_Gestran!$C$2:$C$5481,MATCH(B21,Base_Gestran!$A$2:$A$5481,0)),"NÃO CADASTRADO")) -> NÃO CADASTRADO | F21: ESTOQUE ZERADO | G21: =IF(B21="","",SUMIFS(Base_Gestran!$E$2:$E$5481,Base_Gestran!$A$2:$A$5481,B21,Base_Gestran!$C$2:$C$5481,E21)) -> 0 | H21: PAMCOLD | I21: PENDENTE | L21: =IF(B21="","",B21&"|"&TEXT(A21,"0")) -> CALÇA TÉRMICA -25° G|46267
A22: 46267 | B22: CALÇA TÉRMICA -25° GG | C22: 4 | D22: UND | E22: =IF(B22="","",IFERROR(INDEX(Base_Gestran!$C$2:$C$5481,MATCH(B22,Base_Gestran!$A$2:$A$5481,0)),"NÃO CADASTRADO")) -> NÃO CADASTRADO | F22: ESTOQUE ZERADO | G22: =IF(B22="","",SUMIFS(Base_Gestran!$E$2:$E$5481,Base_Gestran!$A$2:$A$5481,B22,Base_Gestran!$C$2:$C$5481,E22)) -> 0 | H22: PAMCOLD | I22: PENDENTE | L22: =IF(B22="","",B22&"|"&TEXT(A22,"0")) -> CALÇA TÉRMICA -25° GG|46267
A23: 46267 | B23: CALÇA TÉRMICA -45° M | C23: 2 | D23: UND | E23: =IF(B23="","",IFERROR(INDEX(Base_Gestran!$C$2:$C$5481,MATCH(B23,Base_Gestran!$A$2:$A$5481,0)),"NÃO CADASTRADO")) -> NÃO CADASTRADO | F23: ESTOQUE ZERADO | G23: =IF(B23="","",SUMIFS(Base_Gestran!$E$2:$E$5481,Base_Gestran!$A$2:$A$5481,B23,Base_Gestran!$C$2:$C$5481,E23)) -> 0 | H23: PAMCOLD | I23: PENDENTE | L23: =IF(B23="","",B23&"|"&TEXT(A23,"0")) -> CALÇA TÉRMICA -45° M|46267
... A30: 46282 | B30: TANQUE DE LIQUIDO SA1 AC/AE | C30: 1 | D30: UND | E30: =IF(B30="","",IFERROR(INDEX(Base_Gestran!$C$2:$C$5481,MATCH(B30,Base_Gestran!$A$2:$A$5481,0)),"NÃO CADASTRADO")) -> ALMOXARIFADO 1- MANUTENCAO TRANSPORTE | F30: ESTOQUE ZERADO | G30: =IF(B30="","",SUMIFS(Base_Gestran!$E$2:$E$5481,Base_Gestran!$A$2:$A$5481,B30,Base_Gestran!$C$2:$C$5481,E30)) -> 1 | H30: FRIGOKING | I30: PENDENTE | L30: =IF(B30="","",B30&"|"&TEXT(A30,"0")) -> TANQUE DE LIQUIDO SA1 AC/AE |46282
A31: 46282 | B31: PASTILHA SANITÁRIA | C31: =IF(B31="","",IF(SUMIFS(Controle_Estoque!$H$8:$H$150,Controle_Estoque!$A$8:$A$150,B31,Controle_Estoque!$B$8:$B$150,E31)=0,"",SUMIFS(Controle_Estoque!$H$8:$H$150,Controle_Estoque!$A$8:$A$150,B31,Controle_Estoque!$B$8:$B$150,E31))) | E31: =IF(B31="","",IFERROR(INDEX(Base_Gestran!$C$2:$C$5481,MATCH(B31,Base_Gestran!$A$2:$A$5481,0)),"NÃO CADASTRADO")) -> ALMOXARIFADO 5- LIMPEZA | F31: ESTOQUE BAIXO | G31: =IF(B31="","",SUMIFS(Base_Gestran!$E$2:$E$5481,Base_Gestran!$A$2:$A$5481,B31,Base_Gestran!$C$2:$C$5481,E31)) -> 129 | H31: =IF(B31="","",IFERROR(INDEX(Historico_Entradas!$D$2:$D$2009,MATCH(B31&"|"&TEXT(SUMPRODUCT(MAX((Historico_Entradas!$G$2:$G$2009=B31)*Historico_Entradas!$A$2:$A$2009)),"0"),Historico_Entradas!$L$2:$L$2009,0)),"")) | I31: PENDENTE | L31: =IF(B31="","",B31&"|"&TEXT(A31,"0")) -> PASTILHA SANITÁRIA|46282
A32: 46282 | B32: DESENTUPIDOR DE VASO COM CABO | C32: =IF(B32="","",IF(SUMIFS(Controle_Estoque!$H$8:$H$150,Controle_Estoque!$A$8:$A$150,B32,Controle_Estoque!$B$8:$B$150,E32)=0,"",SUMIFS(Controle_Estoque!$H$8:$H$150,Controle_Estoque!$A$8:$A$150,B32,Controle_Estoque!$B$8:$B$150,E32))) -> 33 | E32: =IF(B32="","",IFERROR(INDEX(Base_Gestran!$C$2:$C$5481,MATCH(B32,Base_Gestran!$A$2:$A$5481,0)),"NÃO CADASTRADO")) -> ALMOXARIFADO | F32: ESTOQUE BAIXO | G32: =IF(B32="","",SUMIFS(Base_Gestran!$E$2:$E$5481,Base_Gestran!$A$2:$A$5481,B32,Base_Gestran!$C$2:$C$5481,E32)) -> 1 | H32: =IF(B32="","",IFERROR(INDEX(Historico_Entradas!$D$2:$D$2009,MATCH(B32&"|"&TEXT(SUMPRODUCT(MAX((Historico_Entradas!$G$2:$G$2009=B32)*Historico_Entradas!$A$2:$A$2009)),"0"),Historico_Entradas!$L$2:$L$2009,0)),"")) | I32: PENDENTE | L32: =IF(B32="","",B32&"|"&TEXT(A32,"0")) -> DESENTUPIDOR DE VASO COM CABO|46282
A33: 46287 | B33: CAMISA G AZUL | C33: =IF(B33="","",IF(SUMIFS(Controle_Estoque!$H$8:$H$150,Controle_Estoque!$A$8:$A$150,B33,Controle_Estoque!$B$8:$B$150,E33)=0,"",SUMIFS(Controle_Estoque!$H$8:$H$150,Controle_Estoque!$A$8:$A$150,B33,Controle_Estoque!$B$8:$B$150,E33))) | E33: =IF(B33="","",IFERROR(INDEX(Base_Gestran!$C$2:$C$5481,MATCH(B33,Base_Gestran!$A$2:$A$5481,0)),"NÃO CADASTRADO")) -> NÃO CADASTRADO | F33: ESTOQUE ZERADO | G33: =IF(B33="","",SUMIFS(Base_Gestran!$E$2:$E$5481,Base_Gestran!$A$2:$A$5481,B33,Base_Gestran!$C$2:$C$5481,E33)) -> 0 | H33: =IF(B33="","",IFERROR(INDEX(Historico_Entradas!$D$2:$D$2009,MATCH(B33&"|"&TEXT(SUMPRODUCT(MAX((Historico_Entradas!$G$2:$G$2009=B33)*Historico_Entradas!$A$2:$A$2009)),"0"),Historico_Entradas!$L$2:$L$2009,0)),"")) | I33: PENDENTE | L33: =IF(B33="","",B33&"|"&TEXT(A33,"0")) -> CAMISA G AZUL|46287
A34: 46287 | B34: CAMISA G VERMELHA | C34: =IF(B34="","",IF(SUMIFS(Controle_Estoque!$H$8:$H$150,Controle_Estoque!$A$8:$A$150,B34,Controle_Estoque!$B$8:$B$150,E34)=0,"",SUMIFS(Controle_Estoque!$H$8:$H$150,Controle_Estoque!$A$8:$A$150,B34,Controle_Estoque!$B$8:$B$150,E34))) | E34: =IF(B34="","",IFERROR(INDEX(Base_Gestran!$C$2:$C$5481,MATCH(B34,Base_Gestran!$A$2:$A$5481,0)),"NÃO CADASTRADO")) -> NÃO CADASTRADO | F34: ESTOQUE ZERADO | G34: =IF(B34="","",SUMIFS(Base_Gestran!$E$2:$E$5481,Base_Gestran!$A$2:$A$5481,B34,Base_Gestran!$C$2:$C$5481,E34)) -> 0 | H34: =IF(B34="","",IFERROR(INDEX(Historico_Entradas!$D$2:$D$2009,MATCH(B34&"|"&TEXT(SUMPRODUCT(MAX((Historico_Entradas!$G$2:$G$2009=B34)*Historico_Entradas!$A$2:$A$2009)),"0"),Historico_Entradas!$L$2:$L$2009,0)),"")) | I34: PENDENTE | L34: =IF(B34="","",B34&"|"&TEXT(A34,"0")) -> CAMISA G VERMELHA|46287
A35: 46287 | B35: CONTROLADOR SA1 | C35: =IF(B35="","",IF(SUMIFS(Controle_Estoque!$H$8:$H$150,Controle_Estoque!$A$8:$A$150,B35,Controle_Estoque!$B$8:$B$150,E35)=0,"",SUMIFS(Controle_Estoque!$H$8:$H$150,Controle_Estoque!$A$8:$A$150,B35,Controle_Estoque!$B$8:$B$150,E35))) | E35: =IF(B35="","",IFERROR(INDEX(Base_Gestran!$C$2:$C$5481,MATCH(B35,Base_Gestran!$A$2:$A$5481,0)),"NÃO CADASTRADO")) -> NÃO CADASTRADO | F35: ESTOQUE ZERADO | G35: =IF(B35="","",SUMIFS(Base_Gestran!$E$2:$E$5481,Base_Gestran!$A$2:$A$5481,B35,Base_Gestran!$C$2:$C$5481,E35)) -> 0 | H35: =IF(B35="","",IFERROR(INDEX(Historico_Entradas!$D$2:$D$2009,MATCH(B35&"|"&TEXT(SUMPRODUCT(MAX((Historico_Entradas!$G$2:$G$2009=B35)*Historico_Entradas!$A$2:$A$2009)),"0"),Historico_Entradas!$L$2:$L$2009,0)),"")) | I35: SOLICITADO | L35: =IF(B35="","",B35&"|"&TEXT(A35,"0")) -> CONTROLADOR SA1|46287
A36: 46287 | B36: CHICOTE SA1 | C36: =IF(B36="","",IF(SUMIFS(Controle_Estoque!$H$8:$H$150,Controle_Estoque!$A$8:$A$150,B36,Controle_Estoque!$B$8:$B$150,E36)=0,"",SUMIFS(Controle_Estoque!$H$8:$H$150,Controle_Estoque!$A$8:$A$150,B36,Controle_Estoque!$B$8:$B$150,E36))) | E36: =IF(B36="","",IFERROR(INDEX(Base_Gestran!$C$2:$C$5481,MATCH(B36,Base_Gestran!$A$2:$A$5481,0)),"NÃO CADASTRADO")) -> NÃO CADASTRADO | F36: ESTOQUE ZERADO | G36: =IF(B36="","",SUMIFS(Base_Gestran!$E$2:$E$5481,Base_Gestran!$A$2:$A$5481,B36,Base_Gestran!$C$2:$C$5481,E36)) -> 0 | H36: =IF(B36="","",IFERROR(INDEX(Historico_Entradas!$D$2:$D$2009,MATCH(B36&"|"&TEXT(SUMPRODUCT(MAX((Historico_Entradas!$G$2:$G$2009=B36)*Historico_Entradas!$A$2:$A$2009)),"0"),Historico_Entradas!$L$2:$L$2009,0)),"")) | I36: SOLICITADO | L36: =IF(B36="","",B36&"|"&TEXT(A36,"0")) -> CHICOTE SA1|46287
A37: 46287 | B37: filtro de óleo do motor (accelo 1016 e vw 11.180) | C37: =IF(B37="","",IF(SUMIFS(Controle_Estoque!$H$8:$H$150,Controle_Estoque!$A$8:$A$150,B37,Controle_Estoque!$B$8:$B$150,E37)=0,"",SUMIFS(Controle_Estoque!$H$8:$H$150,Controle_Estoque!$A$8:$A$150,B37,Controle_Estoque!$B$8:$B$150,E37))) | E37: =IF(B37="","",IFERROR(INDEX(Base_Gestran!$C$2:$C$5481,MATCH(B37,Base_Gestran!$A$2:$A$5481,0)),"NÃO CADASTRADO")) -> NÃO CADASTRADO | F37: ESTOQUE ZERADO | G37: =IF(B37="","",SUMIFS(Base_Gestran!$E$2:$E$5481,Base_Gestran!$A$2:$A$5481,B37,Base_Gestran!$C$2:$C$5481,E37)) -> 0 | H37: =IF(B37="","",IFERROR(INDEX(Historico_Entradas!$D$2:$D$2009,MATCH(B37&"|"&TEXT(SUMPRODUCT(MAX((Historico_Entradas!$G$2:$G$2009=B37)*Historico_Entradas!$A$2:$A$2009)),"0"),Historico_Entradas!$L$2:$L$2009,0)),"")) | I37: PENDENTE | L37: =IF(B37="","",B37&"|"&TEXT(A37,"0")) -> filtro de óleo do motor (accelo 1016 e vw 11.180)|46287
A38: 46287 | B38: filtro racor e refil do racor (accelo 1016 e vw 11.180) | C38: =IF(B38="","",IF(SUMIFS(Controle_Estoque!$H$8:$H$150,Controle_Estoque!$A$8:$A$150,B38,Controle_Estoque!$B$8:$B$150,E38)=0,"",SUMIFS(Controle_Estoque!$H$8:$H$150,Controle_Estoque!$A$8:$A$150,B38,Controle_Estoque!$B$8:$B$150,E38))) | E38: =IF(B38="","",IFERROR(INDEX(Base_Gestran!$C$2:$C$5481,MATCH(B38,Base_Gestran!$A$2:$A$5481,0)),"NÃO CADASTRADO")) -> NÃO CADASTRADO | F38: ESTOQUE ZERADO | G38: =IF(B38="","",SUMIFS(Base_Gestran!$E$2:$E$5481,Base_Gestran!$A$2:$A$5481,B38,Base_Gestran!$C$2:$C$5481,E38)) -> 0 | H38: =IF(B38="","",IFERROR(INDEX(Historico_Entradas!$D$2:$D$2009,MATCH(B38&"|"&TEXT(SUMPRODUCT(MAX((Historico_Entradas!$G$2:$G$2009=B38)*Historico_Entradas!$A$2:$A$2009)),"0"),Historico_Entradas!$L$2:$L$2009,0)),"")) | I38: PENDENTE | L38: =IF(B38="","",B38&"|"&TEXT(A38,"0")) -> filtro racor e refil do racor (accelo 1016 e vw 11.180)|46287
A39: 46287 | B39: filtro de ar (accelo 1016 e vw 11.180) | C39: =IF(B39="","",IF(SUMIFS(Controle_Estoque!$H$8:$H$150,Controle_Estoque!$A$8:$A$150,B39,Controle_Estoque!$B$8:$B$150,E39)=0,"",SUMIFS(Controle_Estoque!$H$8:$H$150,Controle_Estoque!$A$8:$A$150,B39,Controle_Estoque!$B$8:$B$150,E39))) | E39: =IF(B39="","",IFERROR(INDEX(Base_Gestran!$C$2:$C$5481,MATCH(B39,Base_Gestran!$A$2:$A$5481,0)),"NÃO CADASTRADO")) -> NÃO CADASTRADO | F39: ESTOQUE ZERADO | G39: =IF(B39="","",SUMIFS(Base_Gestran!$E$2:$E$5481,Base_Gestran!$A$2:$A$5481,B39,Base_Gestran!$C$2:$C$5481,E39)) -> 0 | H39: =IF(B39="","",IFERROR(INDEX(Historico_Entradas!$D$2:$D$2009,MATCH(B39&"|"&TEXT(SUMPRODUCT(MAX((Historico_Entradas!$G$2:$G$2009=B39)*Historico_Entradas!$A$2:$A$2009)),"0"),Historico_Entradas!$L$2:$L$2009,0)),"")) | I39: PENDENTE | L39: =IF(B39="","",B39&"|"&TEXT(A39,"0")) -> filtro de ar (accelo 1016 e vw 11.180)|46287
A40: 46287 | B40: filtro de combustível (accelo 1016 e vw 11.180) | C40: =IF(B40="","",IF(SUMIFS(Controle_Estoque!$H$8:$H$150,Controle_Estoque!$A$8:$A$150,B40,Controle_Estoque!$B$8:$B$150,E40)=0,"",SUMIFS(Controle_Estoque!$H$8:$H$150,Controle_Estoque!$A$8:$A$150,B40,Controle_Estoque!$B$8:$B$150,E40))) | E40: =IF(B40="","",IFERROR(INDEX(Base_Gestran!$C$2:$C$5481,MATCH(B40,Base_Gestran!$A$2:$A$5481,0)),"NÃO CADASTRADO")) -> NÃO CADASTRADO | F40: ESTOQUE ZERADO | G40: =IF(B40="","",SUMIFS(Base_Gestran!$E$2:$E$5481,Base_Gestran!$A$2:$A$5481,B40,Base_Gestran!$C$2:$C$5481,E40)) -> 0 | H40: =IF(B40="","",IFERROR(INDEX(Historico_Entradas!$D$2:$D$2009,MATCH(B40&"|"&TEXT(SUMPRODUCT(MAX((Historico_Entradas!$G$2:$G$2009=B40)*Historico_Entradas!$A$2:$A$2009)),"0"),Historico_Entradas!$L$2:$L$2009,0)),"")) | I40: PENDENTE | L40: =IF(B40="","",B40&"|"&TEXT(A40,"0")) -> filtro de combustível (accelo 1016 e vw 11.180)|46287
A41: 46287 | B41: refletor 50 | C41: =IF(B41="","",IF(SUMIFS(Controle_Estoque!$H$8:$H$150,Controle_Estoque!$A$8:$A$150,B41,Controle_Estoque!$B$8:$B$150,E41)=0,"",SUMIFS(Controle_Estoque!$H$8:$H$150,Controle_Estoque!$A$8:$A$150,B41,Controle_Estoque!$B$8:$B$150,E41))) | E41: =IF(B41="","",IFERROR(INDEX(Base_Gestran!$C$2:$C$5481,MATCH(B41,Base_Gestran!$A$2:$A$5481,0)),"NÃO CADASTRADO")) -> NÃO CADASTRADO | F41: ESTOQUE ZERADO | G41: =IF(B41="","",SUMIFS(Base_Gestran!$E$2:$E$5481,Base_Gestran!$A$2:$A$5481,B41,Base_Gestran!$C$2:$C$5481,E41)) -> 0 | H41: =IF(B41="","",IFERROR(INDEX(Historico_Entradas!$D$2:$D$2009,MATCH(B41&"|"&TEXT(SUMPRODUCT(MAX((Historico_Entradas!$G$2:$G$2009=B41)*Historico_Entradas!$A$2:$A$2009)),"0"),Historico_Entradas!$L$2:$L$2009,0)),"")) | I41: PENDENTE | L41: =IF(B41="","",B41&"|"&TEXT(A41,"0")) -> refletor 50|46287
A42: 46287 | B42: galha de florescente completa 40 | C42: =IF(B42="","",IF(SUMIFS(Controle_Estoque!$H$8:$H$150,Controle_Estoque!$A$8:$A$150,B42,Controle_Estoque!$B$8:$B$150,E42)=0,"",SUMIFS(Controle_Estoque!$H$8:$H$150,Controle_Estoque!$A$8:$A$150,B42,Controle_Estoque!$B$8:$B$150,E42))) | E42: =IF(B42="","",IFERROR(INDEX(Base_Gestran!$C$2:$C$5481,MATCH(B42,Base_Gestran!$A$2:$A$5481,0)),"NÃO CADASTRADO")) -> NÃO CADASTRADO | F42: ESTOQUE ZERADO | G42: =IF(B42="","",SUMIFS(Base_Gestran!$E$2:$E$5481,Base_Gestran!$A$2:$A$5481,B42,Base_Gestran!$C$2:$C$5481,E42)) -> 0 | H42: =IF(B42="","",IFERROR(INDEX(Historico_Entradas!$D$2:$D$2009,MATCH(B42&"|"&TEXT(SUMPRODUCT(MAX((Historico_Entradas!$G$2:$G$2009=B42)*Historico_Entradas!$A$2:$A$2009)),"0"),Historico_Entradas!$L$2:$L$2009,0)),"")) | I42: PENDENTE | L42: =IF(B42="","",B42&"|"&TEXT(A42,"0")) -> galha de florescente completa 40|46287
C43: =IF(B43="","",IF(SUMIFS(Controle_Estoque!$H$8:$H$150,Controle_Estoque!$A$8:$A$150,B43,Controle_Estoque!$B$8:$B$150,E43)=0,"",SUMIFS(Controle_Estoque!$H$8:$H$150,Controle_Estoque!$A$8:$A$150,B43,Controle_Estoque!$B$8:$B$150,E43))) | E43: =IF(B43="","",IFERROR(INDEX(Base_Gestran!$C$2:$C$5481,MATCH(B43,Base_Gestran!$A$2:$A$5481,0)),"NÃO CADASTRADO")) | G43: =IF(B43="","",SUMIFS(Base_Gestran!$E$2:$E$5481,Base_Gestran!$A$2:$A$5481,B43,Base_Gestran!$C$2:$C$5481,E43)) | H43: =IF(B43="","",IFERROR(INDEX(Historico_Entradas!$D$2:$D$2009,MATCH(B43&"|"&TEXT(SUMPRODUCT(MAX((Historico_Entradas!$G$2:$G$2009=B43)*Historico_Entradas!$A$2:$A$2009)),"0"),Historico_Entradas!$L$2:$L$2009,0)),"")) | L43: =IF(B43="","",B43&"|"&TEXT(A43,"0"))
C44: =IF(B44="","",IF(SUMIFS(Controle_Estoque!$H$8:$H$150,Controle_Estoque!$A$8:$A$150,B44,Controle_Estoque!$B$8:$B$150,E44)=0,"",SUMIFS(Controle_Estoque!$H$8:$H$150,Controle_Estoque!$A$8:$A$150,B44,Controle_Estoque!$B$8:$B$150,E44))) | E44: =IF(B44="","",IFERROR(INDEX(Base_Gestran!$C$2:$C$5481,MATCH(B44,Base_Gestran!$A$2:$A$5481,0)),"NÃO CADASTRADO")) | G44: =IF(B44="","",SUMIFS(Base_Gestran!$E$2:$E$5481,Base_Gestran!$A$2:$A$5481,B44,Base_Gestran!$C$2:$C$5481,E44)) | H44: =IF(B44="","",IFERROR(INDEX(Historico_Entradas!$D$2:$D$2009,MATCH(B44&"|"&TEXT(SUMPRODUCT(MAX((Historico_Entradas!$G$2:$G$2009=B44)*Historico_Entradas!$A$2:$A$2009)),"0"),Historico_Entradas!$L$2:$L$2009,0)),"")) | L44: =IF(B44="","",B44&"|"&TEXT(A44,"0"))
C45: =IF(B45="","",IF(SUMIFS(Controle_Estoque!$H$8:$H$150,Controle_Estoque!$A$8:$A$150,B45,Controle_Estoque!$B$8:$B$150,E45)=0,"",SUMIFS(Controle_Estoque!$H$8:$H$150,Controle_Estoque!$A$8:$A$150,B45,Controle_Estoque!$B$8:$B$150,E45))) | E45: =IF(B45="","",IFERROR(INDEX(Base_Gestran!$C$2:$C$5481,MATCH(B45,Base_Gestran!$A$2:$A$5481,0)),"NÃO CADASTRADO")) | G45: =IF(B45="","",SUMIFS(Base_Gestran!$E$2:$E$5481,Base_Gestran!$A$2:$A$5481,B45,Base_Gestran!$C$2:$C$5481,E45)) | H45: =IF(B45="","",IFERROR(INDEX(Historico_Entradas!$D$2:$D$2009,MATCH(B45&"|"&TEXT(SUMPRODUCT(MAX((Historico_Entradas!$G$2:$G$2009=B45)*Historico_Entradas!$A$2:$A$2009)),"0"),Historico_Entradas!$L$2:$L$2009,0)),"")) | L45: =IF(B45="","",B45&"|"&TEXT(A45,"0")) | M45: =IF(B45="","",IF(SUMIFS(Base_Gestran!$H$2:$H$5481,Base_Gestran!$A$2:$A$5481,B45,Base_Gestran!$C$2:$C$5481,E45)=0,"",SUMIFS(Base_Gestran!$H$2:$H$5481,Base_Gestran!$A$2:$A$5481,B45,Base_Gestran!$C$2:$C$5481,E45)))
C46: =IF(B46="","",IF(SUMIFS(Controle_Estoque!$H$8:$H$150,Controle_Estoque!$A$8:$A$150,B46,Controle_Estoque!$B$8:$B$150,E46)=0,"",SUMIFS(Controle_Estoque!$H$8:$H$150,Controle_Estoque!$A$8:$A$150,B46,Controle_Estoque!$B$8:$B$150,E46))) | E46: =IF(B46="","",IFERROR(INDEX(Base_Gestran!$C$2:$C$5481,MATCH(B46,Base_Gestran!$A$2:$A$5481,0)),"NÃO CADASTRADO")) | G46: =IF(B46="","",SUMIFS(Base_Gestran!$E$2:$E$5481,Base_Gestran!$A$2:$A$5481,B46,Base_Gestran!$C$2:$C$5481,E46)) | H46: =IF(B46="","",IFERROR(INDEX(Historico_Entradas!$D$2:$D$2009,MATCH(B46&"|"&TEXT(SUMPRODUCT(MAX((Historico_Entradas!$G$2:$G$2009=B46)*Historico_Entradas!$A$2:$A$2009)),"0"),Historico_Entradas!$L$2:$L$2009,0)),"")) | L46: =IF(B46="","",B46&"|"&TEXT(A46,"0")) | M46: =IF(B46="","",IF(SUMIFS(Base_Gestran!$H$2:$H$5481,Base_Gestran!$A$2:$A$5481,B46,Base_Gestran!$C$2:$C$5481,E46)=0,"",SUMIFS(Base_Gestran!$H$2:$H$5481,Base_Gestran!$A$2:$A$5481,B46,Base_Gestran!$C$2:$C$5481,E46)))
...

Sheet Analises_Gerais
A1: ANÁLISE GERAL DO ESTOQUE — VISÃO PARA A DIRETORIA
A2: Baseado no export do Gestran (aba Base_Gestran). Atualiza sozinho quando você colar um novo export.
A4: Total de cadastros (linhas) na base | B4: =COUNTA(Base_Gestran!A2:A5481) -> 5480
A5: Cadastros com saldo físico > 0 | B5: =COUNTIFS(Base_Gestran!E2:E5481,">0") -> 4484
A6: Cadastros com saldo ZERADO | B6: =COUNTIFS(Base_Gestran!E2:E5481,0) -> 990
A7: Cadastros com saldo NEGATIVO (erro a corrigir) | B7: =COUNTIFS(Base_Gestran!E2:E5481,"<0") -> 6
A8: % da base realmente com estoque | B8: =B5/B4 -> 0.81824818
A9: Valor total em estoque (R$) | B9: =SUM(Base_Gestran!J2:J5481) -> 5119194.7
A10: Cadastros sem NENHUM registro de saída (parados) | B10: =COUNTIFS(Base_Gestran!G2:G5481,"") -> 3461
A11: Produtos com mesmo nome cadastrado em +1 registro (possível marca/local fragmentado) | B11: =COUNTIFS(Base_Gestran!M2:M5481,">1") -> 1492
A13: TOP 20 ITENS POR VALOR PARADO EM ESTOQUE
A14: POSIÇÃO | B14: Produto | C14: Almoxarifado | D14: Saldo | E14: Valor Total em Estoque (R$)
A15: 1 | B15: =INDEX(Base_Gestran!$A$2:$A$5481,MATCH(LARGE(Base_Gestran!$N$2:$N$5481,1),Base_Gestran!$N$2:$N$5481,0)) -> SCS PLAST TR PR LISO 20 x 30 | C15: =INDEX(Base_Gestran!$C$2:$C$5481,MATCH(LARGE(Base_Gestran!$N$2:$N$5481,1),Base_Gestran!$N$2:$N$5481,0)) -> ALMOXARIFADO 7- INDUSTRIA | D15: =INDEX(Base_Gestran!$E$2:$E$5481,MATCH(LARGE(Base_Gestran!$N$2:$N$5481,1),Base_Gestran!$N$2:$N$5481,0)) -> 3813.4 | E15: =INDEX(Base_Gestran!$J$2:$J$5481,MATCH(LARGE(Base_Gestran!$N$2:$N$5481,1),Base_Gestran!$N$2:$N$5481,0)) -> 1271273.2
A16: 2 | B16: =INDEX(Base_Gestran!$A$2:$A$5481,MATCH(LARGE(Base_Gestran!$N$2:$N$5481,2),Base_Gestran!$N$2:$N$5481,0)) -> METALON GALVANIZADO 30X50X18 | C16: =INDEX(Base_Gestran!$C$2:$C$5481,MATCH(LARGE(Base_Gestran!$N$2:$N$5481,2),Base_Gestran!$N$2:$N$5481,0)) -> ALMOXARIFADO | D16: =INDEX(Base_Gestran!$E$2:$E$5481,MATCH(LARGE(Base_Gestran!$N$2:$N$5481,2),Base_Gestran!$N$2:$N$5481,0)) -> 4 | E16: =INDEX(Base_Gestran!$J$2:$J$5481,MATCH(LARGE(Base_Gestran!$N$2:$N$5481,2),Base_Gestran!$N$2:$N$5481,0)) -> 416800
A17: 3 | B17: =INDEX(Base_Gestran!$A$2:$A$5481,MATCH(LARGE(Base_Gestran!$N$2:$N$5481,3),Base_Gestran!$N$2:$N$5481,0)) -> STRETCH MANUAL 500MM X 25 MICRA X 3 | C17: =INDEX(Base_Gestran!$C$2:$C$5481,MATCH(LARGE(Base_Gestran!$N$2:$N$5481,3),Base_Gestran!$N$2:$N$5481,0)) -> ALMOXARIFADO 9- LOGÍSTICA | D17: =INDEX(Base_Gestran!$E$2:$E$5481,MATCH(LARGE(Base_Gestran!$N$2:$N$5481,3),Base_Gestran!$N$2:$N$5481,0)) -> 12263.52 | E17: =INDEX(Base_Gestran!$J$2:$J$5481,MATCH(LARGE(Base_Gestran!$N$2:$N$5481,3),Base_Gestran!$N$2:$N$5481,0)) -> 241713.98
A18: 4 | B18: =INDEX(Base_Gestran!$A$2:$A$5481,MATCH(LARGE(Base_Gestran!$N$2:$N$5481,4),Base_Gestran!$N$2:$N$5481,0)) -> ROLAMENTO 6004ZE MARCA NACHI | C18: =INDEX(Base_Gestran!$C$2:$C$5481,MATCH(LARGE(Base_Gestran!$N$2:$N$5481,4),Base_Gestran!$N$2:$N$5481,0)) -> ALMOXARIFADO | D18: =INDEX(Base_Gestran!$E$2:$E$5481,MATCH(LARGE(Base_Gestran!$N$2:$N$5481,4),Base_Gestran!$N$2:$N$5481,0)) -> 3000 | E18: =INDEX(Base_Gestran!$J$2:$J$5481,MATCH(LARGE(Base_Gestran!$N$2:$N$5481,4),Base_Gestran!$N$2:$N$5481,0)) -> 135000
A19: 5 | B19: =INDEX(Base_Gestran!$A$2:$A$5481,MATCH(LARGE(Base_Gestran!$N$2:$N$5481,5),Base_Gestran!$N$2:$N$5481,0)) -> CX CV 25KG FUNDO | C19: =INDEX(Base_Gestran!$C$2:$C$5481,MATCH(LARGE(Base_Gestran!$N$2:$N$5481,5),Base_Gestran!$N$2:$N$5481,0)) -> ALMOXARIFADO 7- INDUSTRIA | D19: =INDEX(Base_Gestran!$E$2:$E$5481,MATCH(LARGE(Base_Gestran!$N$2:$N$5481,5),Base_Gestran!$N$2:$N$5481,0)) -> 20966 | E19: =INDEX(Base_Gestran!$J$2:$J$5481,MATCH(LARGE(Base_Gestran!$N$2:$N$5481,5),Base_Gestran!$N$2:$N$5481,0)) -> 96443.6
A20: 6 | B20: =INDEX(Base_Gestran!$A$2:$A$5481,MATCH(LARGE(Base_Gestran!$N$2:$N$5481,6),Base_Gestran!$N$2:$N$5481,0)) -> CX CV 15KG FUNDO | C20: =INDEX(Base_Gestran!$C$2:$C$5481,MATCH(LARGE(Base_Gestran!$N$2:$N$5481,6),Base_Gestran!$N$2:$N$5481,0)) -> ALMOXARIFADO 7- INDUSTRIA | D20: =INDEX(Base_Gestran!$E$2:$E$5481,MATCH(LARGE(Base_Gestran!$N$2:$N$5481,6),Base_Gestran!$N$2:$N$5481,0)) -> 15781 | E20: =INDEX(Base_Gestran!$J$2:$J$5481,MATCH(LARGE(Base_Gestran!$N$2:$N$5481,6),Base_Gestran!$N$2:$N$5481,0)) -> 64859.91
A21: 7 | B21: =INDEX(Base_Gestran!$A$2:$A$5481,MATCH(LARGE(Base_Gestran!$N$2:$N$5481,7),Base_Gestran!$N$2:$N$5481,0)) -> ETIQUETA PERSONALIZADA - INTERNO BOIBOM | C21: =INDEX(Base_Gestran!$C$2:$C$5481,MATCH(LARGE(Base_Gestran!$N$2:$N$5481,7),Base_Gestran!$N$2:$N$5481,0)) -> ALMOXARIFADO 7- INDUSTRIA | D21: =INDEX(Base_Gestran!$E$2:$E$5481,MATCH(LARGE(Base_Gestran!$N$2:$N$5481,7),Base_Gestran!$N$2:$N$5481,0)) -> 788000 | E21: =INDEX(Base_Gestran!$J$2:$J$5481,MATCH(LARGE(Base_Gestran!$N$2:$N$5481,7),Base_Gestran!$N$2:$N$5481,0)) -> 63040
A22: 8 | B22: =INDEX(Base_Gestran!$A$2:$A$5481,MATCH(LARGE(Base_Gestran!$N$2:$N$5481,8),Base_Gestran!$N$2:$N$5481,0)) -> CX CV 15KG TAMPA | C22: =INDEX(Base_Gestran!$C$2:$C$5481,MATCH(LARGE(Base_Gestran!$N$2:$N$5481,8),Base_Gestran!$N$2:$N$5481,0)) -> ALMOXARIFADO 7- INDUSTRIA | D22: =INDEX(Base_Gestran!$E$2:$E$5481,MATCH(LARGE(Base_Gestran!$N$2:$N$5481,8),Base_Gestran!$N$2:$N$5481,0)) -> 13269 | E22: =INDEX(Base_Gestran!$J$2:$J$5481,MATCH(LARGE(Base_Gestran!$N$2:$N$5481,8),Base_Gestran!$N$2:$N$5481,0)) -> 63027.75
A23: 9 | B23: =INDEX(Base_Gestran!$A$2:$A$5481,MATCH(LARGE(Base_Gestran!$N$2:$N$5481,9),Base_Gestran!$N$2:$N$5481,0)) -> CX CV 25KG TAMPA | C23: =INDEX(Base_Gestran!$C$2:$C$5481,MATCH(LARGE(Base_Gestran!$N$2:$N$5481,9),Base_Gestran!$N$2:$N$5481,0)) -> ALMOXARIFADO 7- INDUSTRIA | D23: =INDEX(Base_Gestran!$E$2:$E$5481,MATCH(LARGE(Base_Gestran!$N$2:$N$5481,9),Base_Gestran!$N$2:$N$5481,0)) -> 12961 | E23: =INDEX(Base_Gestran!$J$2:$J$5481,MATCH(LARGE(Base_Gestran!$N$2:$N$5481,9),Base_Gestran!$N$2:$N$5481,0)) -> 55732.3
A24: 10 | B24: =INDEX(Base_Gestran!$A$2:$A$5481,MATCH(LARGE(Base_Gestran!$N$2:$N$5481,10),Base_Gestran!$N$2:$N$5481,0)) -> FLUIDO REF R404A HP62 ONU 3337 | C24: =INDEX(Base_Gestran!$C$2:$C$5481,MATCH(LARGE(Base_Gestran!$N$2:$N$5481,10),Base_Gestran!$N$2:$N$5481,0)) -> ALMOXARIFADO 0- GERAL | D24: =INDEX(Base_Gestran!$E$2:$E$5481,MATCH(LARGE(Base_Gestran!$N$2:$N$5481,10),Base_Gestran!$N$2:$N$5481,0)) -> 501.4 | E24: =INDEX(Base_Gestran!$J$2:$J$5481,MATCH(LARGE(Base_Gestran!$N$2:$N$5481,10),Base_Gestran!$N$2:$N$5481,0)) -> 42027.348
A25: 11 | B25: =INDEX(Base_Gestran!$A$2:$A$5481,MATCH(LARGE(Base_Gestran!$N$2:$N$5481,11),Base_Gestran!$N$2:$N$5481,0)) -> FLUIDO REF R404A HP62 ONU 3337 | C25: =INDEX(Base_Gestran!$C$2:$C$5481,MATCH(LARGE(Base_Gestran!$N$2:$N$5481,11),Base_Gestran!$N$2:$N$5481,0)) -> ALMOXARIFADO 1- MANUTENCAO TRANSPORTE | D25: =INDEX(Base_Gestran!$E$2:$E$5481,MATCH(LARGE(Base_Gestran!$N$2:$N$5481,11),Base_Gestran!$N$2:$N$5481,0)) -> 468.3 | E25: =INDEX(Base_Gestran!$J$2:$J$5481,MATCH(LARGE(Base_Gestran!$N$2:$N$5481,11),Base_Gestran!$N$2:$N$5481,0)) -> 39529.203
A26: 12 | B26: =INDEX(Base_Gestran!$A$2:$A$5481,MATCH(LARGE(Base_Gestran!$N$2:$N$5481,12),Base_Gestran!$N$2:$N$5481,0)) -> PAPEL TOALHA BOBINA 6X20X200 | C26: =INDEX(Base_Gestran!$C$2:$C$5481,MATCH(LARGE(Base_Gestran!$N$2:$N$5481,12),Base_Gestran!$N$2:$N$5481,0)) -> ALMOXARIFADO 5- LIMPEZA | D26: =INDEX(Base_Gestran!$E$2:$E$5481,MATCH(LARGE(Base_Gestran!$N$2:$N$5481,12),Base_Gestran!$N$2:$N$5481,0)) -> 1044 | E26: =INDEX(Base_Gestran!$J$2:$J$5481,MATCH(LARGE(Base_Gestran!$N$2:$N$5481,12),Base_Gestran!$N$2:$N$5481,0)) -> 29764.44
A27: 13 | B27: =INDEX(Base_Gestran!$A$2:$A$5481,MATCH(LARGE(Base_Gestran!$N$2:$N$5481,13),Base_Gestran!$N$2:$N$5481,0)) -> BOPP BRANCO FOSCO FASSON S 2045 90MTS ZEBRA | C27: =INDEX(Base_Gestran!$C$2:$C$5481,MATCH(LARGE(Base_Gestran!$N$2:$N$5481,13),Base_Gestran!$N$2:$N$5481,0)) -> ALMOXARIFADO 9- LOGÍSTICA | D27: =INDEX(Base_Gestran!$E$2:$E$5481,MATCH(LARGE(Base_Gestran!$N$2:$N$5481,13),Base_Gestran!$N$2:$N$5481,0)) -> 329 | E27: =INDEX(Base_Gestran!$J$2:$J$5481,MATCH(LARGE(Base_Gestran!$N$2:$N$5481,13),Base_Gestran!$N$2:$N$5481,0)) -> 29100.05
A28: 14 | B28: =INDEX(Base_Gestran!$A$2:$A$5481,MATCH(LARGE(Base_Gestran!$N$2:$N$5481,14),Base_Gestran!$N$2:$N$5481,0)) -> SCS PLAST LISO NAT 20X51 | C28: =INDEX(Base_Gestran!$C$2:$C$5481,MATCH(LARGE(Base_Gestran!$N$2:$N$5481,14),Base_Gestran!$N$2:$N$5481,0)) -> ALMOXARIFADO 7- INDUSTRIA | D28: =INDEX(Base_Gestran!$E$2:$E$5481,MATCH(LARGE(Base_Gestran!$N$2:$N$5481,14),Base_Gestran!$N$2:$N$5481,0)) -> 142.6 | E28: =INDEX(Base_Gestran!$J$2:$J$5481,MATCH(LARGE(Base_Gestran!$N$2:$N$5481,14),Base_Gestran!$N$2:$N$5481,0)) -> 25409.894
A29: 15 | B29: =INDEX(Base_Gestran!$A$2:$A$5481,MATCH(LARGE(Base_Gestran!$N$2:$N$5481,15),Base_Gestran!$N$2:$N$5481,0)) -> LAVADORA A260 N/SERIE: 30201444 | C29: =INDEX(Base_Gestran!$C$2:$C$5481,MATCH(LARGE(Base_Gestran!$N$2:$N$5481,15),Base_Gestran!$N$2:$N$5481,0)) -> ALMOXARIFADO 2- MANUTENCAO PREDIAL | D29: =INDEX(Base_Gestran!$E$2:$E$5481,MATCH(LARGE(Base_Gestran!$N$2:$N$5481,15),Base_Gestran!$N$2:$N$5481,0)) -> 1 | E29: =INDEX(Base_Gestran!$J$2:$J$5481,MATCH(LARGE(Base_Gestran!$N$2:$N$5481,15),Base_Gestran!$N$2:$N$5481,0)) -> 25000
A30: 16 | B30: =INDEX(Base_Gestran!$A$2:$A$5481,MATCH(LARGE(Base_Gestran!$N$2:$N$5481,16),Base_Gestran!$N$2:$N$5481,0)) -> OLEO M-DELVAC MODERN 15W40 SD V3 MARCA M-DELVAC | C30: =INDEX(Base_Gestran!$C$2:$C$5481,MATCH(LARGE(Base_Gestran!$N$2:$N$5481,16),Base_Gestran!$N$2:$N$5481,0)) -> ALMOXARIFADO 1- MANUTENCAO TRANSPORTE | D30: =INDEX(Base_Gestran!$E$2:$E$5481,MATCH(LARGE(Base_Gestran!$N$2:$N$5481,16),Base_Gestran!$N$2:$N$5481,0)) -> 1200 | E30: =INDEX(Base_Gestran!$J$2:$J$5481,MATCH(LARGE(Base_Gestran!$N$2:$N$5481,16),Base_Gestran!$N$2:$N$5481,0)) -> 22920
A31: 17 | B31: =INDEX(Base_Gestran!$A$2:$A$5481,MATCH(LARGE(Base_Gestran!$N$2:$N$5481,17),Base_Gestran!$N$2:$N$5481,0)) -> ADITIVO DE RADIADOR | C31: =INDEX(Base_Gestran!$C$2:$C$5481,MATCH(LARGE(Base_Gestran!$N$2:$N$5481,17),Base_Gestran!$N$2:$N$5481,0)) -> ALMOXARIFADO 1- MANUTENCAO TRANSPORTE | D31: =INDEX(Base_Gestran!$E$2:$E$5481,MATCH(LARGE(Base_Gestran!$N$2:$N$5481,17),Base_Gestran!$N$2:$N$5481,0)) -> 1240 | E31: =INDEX(Base_Gestran!$J$2:$J$5481,MATCH(LARGE(Base_Gestran!$N$2:$N$5481,17),Base_Gestran!$N$2:$N$5481,0)) -> 19616.8
A32: 18 | B32: =INDEX(Base_Gestran!$A$2:$A$5481,MATCH(LARGE(Base_Gestran!$N$2:$N$5481,18),Base_Gestran!$N$2:$N$5481,0)) -> ANEL CAMBIO FSO 4505A (ACCELO 1016) | C32: =INDEX(Base_Gestran!$C$2:$C$5481,MATCH(LARGE(Base_Gestran!$N$2:$N$5481,18),Base_Gestran!$N$2:$N$5481,0)) -> ALMOXARIFADO | D32: =INDEX(Base_Gestran!$E$2:$E$5481,MATCH(LARGE(Base_Gestran!$N$2:$N$5481,18),Base_Gestran!$N$2:$N$5481,0)) -> 1 | E32: =INDEX(Base_Gestran!$J$2:$J$5481,MATCH(LARGE(Base_Gestran!$N$2:$N$5481,18),Base_Gestran!$N$2:$N$5481,0)) -> 19000
A33: 19 | B33: =INDEX(Base_Gestran!$A$2:$A$5481,MATCH(LARGE(Base_Gestran!$N$2:$N$5481,19),Base_Gestran!$N$2:$N$5481,0)) -> CX CV 25KG TAMPA | C33: =INDEX(Base_Gestran!$C$2:$C$5481,MATCH(LARGE(Base_Gestran!$N$2:$N$5481,19),Base_Gestran!$N$2:$N$5481,0)) -> ALMOXARIFADO 9- LOGÍSTICA | D33: =INDEX(Base_Gestran!$E$2:$E$5481,MATCH(LARGE(Base_Gestran!$N$2:$N$5481,19),Base_Gestran!$N$2:$N$5481,0)) -> 4275 | E33: =INDEX(Base_Gestran!$J$2:$J$5481,MATCH(LARGE(Base_Gestran!$N$2:$N$5481,19),Base_Gestran!$N$2:$N$5481,0)) -> 18596.25
A34: 20 | B34: =INDEX(Base_Gestran!$A$2:$A$5481,MATCH(LARGE(Base_Gestran!$N$2:$N$5481,20),Base_Gestran!$N$2:$N$5481,0)) -> SCS PLAST TR PR LISO 43 x 70 | C34: =INDEX(Base_Gestran!$C$2:$C$5481,MATCH(LARGE(Base_Gestran!$N$2:$N$5481,20),Base_Gestran!$N$2:$N$5481,0)) -> ALMOXARIFADO 7- INDUSTRIA | D34: =INDEX(Base_Gestran!$E$2:$E$5481,MATCH(LARGE(Base_Gestran!$N$2:$N$5481,20),Base_Gestran!$N$2:$N$5481,0)) -> 44.8 | E34: =INDEX(Base_Gestran!$J$2:$J$5481,MATCH(LARGE(Base_Gestran!$N$2:$N$5481,20),Base_Gestran!$N$2:$N$5481,0)) -> 18012.736
A36: Nota: 'Chave Único' na Base_Gestran (coluna N) é só um auxiliar de cálculo para o ranking acima — não é um dado do sistema.
A38: OBSERVAÇÕES IDENTIFICADAS NA CONFERÊNCIA MANUAL DE HOJE

Sheet Historico_Saidas
A1: HISTÓRICO DE SAÍDAS — para calcular consumo médio automaticamente | F1: Semanas cobertas pelo período puxado | G1: =(MAX($C$6:$C$5000)-MIN($C$6:$C$5000))/7 -> 36.341607
A2: Cole aqui o extrato de movimentação de cada item (Data + Quantidade da saída). Pode colar os 3 trimestres, um embaixo do outro — não precisa apagar o anterior, só ir acrescentando linhas novas. | F2: Ex: Jan a Set = 9 meses ≈ 39 semanas. Ajuste aqui se puxar período diferente.
A4: Item (Produto) — mesmo nome usado no Painel | B4: Almoxarifado (Local) | C4: Data da Saída | D4: Quantidade
A5: EXEMPLO: BUZINA BIBI 24V | B5: ALMOXARIFADO | C5: 2026-08-05 | D5: 2
A6: LAMPADA H4 24V PHILLIPS | B6: ALMOXARIFADO | C6: 46029.394 | D6: 1
A7: LAMPADA H4 24V PHILLIPS | B7: ALMOXARIFADO | C7: 46029.395 | D7: 1
A8: LAMPADA R5 24V MARCA PHILLIPS | B8: ALMOXARIFADO | C8: 46029.395 | D8: 1
A9: FAROL DE MILHA - LED (REDONDO) | B9: ALMOXARIFADO | C9: 46029.4 | D9: 1
A10: BOTÃO TIC TAC | B10: ALMOXARIFADO | C10: 46029.4 | D10: 1
A11: LAMPADA R5 24V MARCA PHILLIPS | B11: ALMOXARIFADO | C11: 46029.4 | D11: 1
A12: LAMPADA H4 24V PHILLIPS | B12: ALMOXARIFADO | C12: 46029.403 | D12: 1
A13: LAMPADA H7 24V PHILLIPS | B13: ALMOXARIFADO | C13: 46029.404 | D13: 1
A14: LAMPADA 1 POLO 24V | B14: ALMOXARIFADO | C14: 46029.405 | D14: 1
A15: CABO LIGAÇAO FECHADURA ACCELO (LD) (LE) | B15: ALMOXARIFADO | C15: 46029.407 | D15: 1
A16: MACANETA INTERNA ESQUERDA ACCELO / 3233 - A | B16: ALMOXARIFADO | C16: 46029.407 | D16: 1
A17: LAMPADA R5 24V MARCA PHILLIPS | B17: ALMOXARIFADO | C17: 46029.416 | D17: 1
... A1513: COPO DESCARTÁVEL 200ML COPOMAIS | B1513: ALMOXARIFADO 5- LIMPEZA | C1513: 46283.785 | D1513: 4

Sheet Base_Gestran
